Workbook

Sheet アンケート結果
A1: タイムスタンプ | B1: 社員番号 | C1: 氏名 | D1: 研修名をお選び下さい。 | E1: 担当した講師名をお選び下さい。 | F1: ① 研修に満足しましたか？（全く思わない：1、思わない：2、思う：3、強く思う：4） | G1: ② 研修内容は理解出来ましたか？（全く理解出来ていない：1、理解出来ていない：2、理解出来ている：3、十分に理解出来ている：4） | H1: ③ 研修で新たな学びは得られましたか？または必要な知識は得られましたか？（全く得られていない：1、得られていない：2、得られている：3、十分に得られている：4） | I1: ④ 研修内容のボリュームは適切でしたか？（全く適切ではない：1、適切ではない：2、適切である：3、十分に適切である：4） | J1: ⑤ 研修のテキスト、教材に対して満足しましたか？（全く思わない：1、思わない：2、思う：3、強く思う：4） | K1: ⑥ 講師の講義、あるいはフィードバックに対して満足しましたか？（全く思わない：1、思わない：2、思う：3、強く思う：4） | L1: ⑦ 講師は研修内容に関する知識を持っていましたか ？（全く持っていない：1、持っていない：2、持っている：3、十分に持っている：4） | M1: ⑧ 今回の研修で学んだことを、今後の業務で実践する機会はありそうですか？ | N1: ⑨ 研修に対する感想や要望などあれば、自由にご記入下さい。 | O1: ➉ 講師に対する感想や要望などあれば、自由にご記入下さい。 | P1: 受講時期
A2: 45875.741 | B2: 586 | C2: 鈴木 健斗 | D2: プロジェクトマネージャー実践研修 | E2: 永谷 裕子 (プロジェクトマネージャー実践研修担当) | F2: 4 | G2: 4 | H2: 4 | I2: 4 | J2: 4 | K2: 4 | L2: 4 | M2: ある | P2: 第1期
A3: 45875.741 | B3: 1295 | C3: 望月洋平 | D3: プロジェクトマネージャー実践研修 | E3: 永谷 裕子 (プロジェクトマネージャー実践研修担当) | F3: 4 | G3: 4 | H3: 4 | I3: 3 | J3: 3 | K3: 3 | L3: 4 | M3: ある | N3: 座学より演習時間を増やしてほしい | P3: 第1期
A4: 45875.742 | B4: 1117 | C4: 廣田慎太郎 | D4: プロジェクトマネージャー実践研修 | E4: 永谷 裕子 (プロジェクトマネージャー実践研修担当) | F4: 4 | G4: 4 | H4: 4 | I4: 4 | J4: 4 | K4: 4 | L4: 4 | M4: ある | N4: PCを利用しない形式なので良かった。→PC利用するとどうしても仕事をしてしまう場面があるため。 ワークの題材について、引越じゃなく、具体的なIT関連PJにしても良かったと思う(参加者が全員IT経験者のため) | O4: 所々で体験談を挟んでいただいた点が良かったです。ありがとうごさいました。 | P4: 第1期
A5: 45875.742 | B5: 604 | C5: 田中弘紀 | D5: プロジェクトマネージャー実践研修 | E5: 永谷 裕子 (プロジェクトマネージャー実践研修担当) | F5: 3 | G5: 4 | H5: 4 | I5: 4 | J5: 3 | K5: 3 | L5: 4 | M5: ある | N5: 模造紙に手書きでは無く、スプレッドシートやスライドなどで実習に取り組めたら やりやすいと感じました。 | P5: 第1期
A6: 45875.742 | B6: 1350 | C6: 齋藤ダイキ | D6: プロジェクトマネージャー実践研修 | E6: 永谷 裕子 (プロジェクトマネージャー実践研修担当) | F6: 4 | G6: 3 | H6: 4 | I6: 4 | J6: 4 | K6: 4 | L6: 4 | M6: ある | N6: PMでは無いので、PMがどのようなことを考えて業務を行なっているか学びながら体験できてとても良かった | O6: 実務を行なっていた講師なので、踏み込んだ話を聞けたし、いろいろ話ししてくれて楽しい研修だなと感じた | P6: 第1期
A7: 45875.742 | B7: 1140 | C7: 長谷川 裕昭 | D7: プロジェクトマネージャー実践研修 | E7: 永谷 裕子 (プロジェクトマネージャー実践研修担当) | F7: 4 | G7: 4 | H7: 3 | I7: 4 | J7: 4 | K7: 3 | L7: 4 | M7: ある | N7: PMとしてどうするべきか、何をするべきか、何を考えるべきかなど、学び考えることができ非常にいい経験になりました。 | P7: 第1期
A8: 45875.742 | B8: 367 | C8: 小谷大基 | D8: プロジェクトマネージャー実践研修 | E8: 永谷 裕子 (プロジェクトマネージャー実践研修担当) | F8: 4 | G8: 4 | H8: 4 | I8: 4 | J8: 4 | K8: 4 | L8: 4 | M8: ある | N8: PM目指すかどうか関係無くプロジェクト進行についての大事な知識が詰まっているのでうちのエンジニアが全員受けるべきだと思いました。 | O8: 永谷先生の説明は非常に分かりやすく、自己学習でわからなかった点がクリアになってよかったです。 | P8: 第1期
A9: 45875.743 | B9: 1315 | C9: 小畑アリス | D9: プロジェクトマネージャー実践研修 | E9: 永谷 裕子 (プロジェクトマネージャー実践研修担当) | F9: 4 | G9: 4 | H9: 4 | I9: 4 | J9: 4 | K9: 4 | L9: 4 | M9: ある | N9: ワークがたくさんあり楽しかったです。実際に現在担当しているプロジェクトで不安に思ってることや解決策とかを学べました。仕事から離れて対面でやる勉強会はオンラインよりたくさん吸収できたように思います。ありがとうございました。 | O9: ２日間ありがとうございました。いつもワークの発表をした際に、みんなの意見に対して、いいね！と褒めてくださったのがすごく印象的でしたし、日々のMTGで私も真似しようと思いました。pmbokは、本が分厚くて勉強する気にならなかったので、対面でワークたくさんで勉強できたのはすごくありがたかったです。ありがとうございました。これから、PM頑張ります。 | P9: 第1期
A10: 45875.743 | B10: 494 | C10: 阿部幸司 | D10: プロジェクトマネージャー実践研修 | E10: 永谷 裕子 (プロジェクトマネージャー実践研修担当) | F10: 4 | G10: 4 | H10: 4 | I10: 3 | J10: 4 | K10: 4 | L10: 4 | M10: ある | N10: 漠然と知っていたことを体系として知れてよかったです。短い時間の中で要点を押さえての研修だったと思うのでまだまだ奥深いと思っているので復習と自己学習、アウトプットをして忘れないようにしていきたいとおもいます。 | O10: 実際の経験からのお話があってより現場を感じられてよかったです。 | P10: 第1期
A11: 45875.744 | B11: 1332 | C11: 江端隼樹 | D11: プロジェクトマネージャー実践研修 | E11: 永谷 裕子 (プロジェクトマネージャー実践研修担当) | F11: 4 | G11: 4 | H11: 4 | I11: 4 | J11: 4 | K11: 4 | L11: 4 | M11: ある | N11: 今まではっきりとPMという形で参画したプロジェクトはなかったが、WBSの作成やガントチャートは自分なりに作っていた。 ハードスキルは知っていることもあったが、ソフトスキルは知らないことも多かったので、これから身につけたい | O11: 永谷さんの経験もたくさん話してくださり、参考になりました | P11: 第1期
A12: 45875.744 | B12: 345 | C12: 謝花 彰一 | D12: プロジェクトマネージャー実践研修 | E12: 永谷 裕子 (プロジェクトマネージャー実践研修担当) | F12: 4 | G12: 3 | H12: 4 | I12: 3 | J12: 2 | K12: 4 | L12: 4 | M12: ある | N12: 実践パートがもう少し多ければいいかなと思いました。 | O12: 色々な自身の経験談があり楽しく進められた、マネジメントに対する知識も凄いなと思いました。 | P12: 第1期
A13: 45875.745 | B13: 1152 | C13: 片山健太郎 | D13: プロジェクトマネージャー実践研修 | E13: 永谷 裕子 (プロジェクトマネージャー実践研修担当) | F13: 4 | G13: 3 | H13: 4 | I13: 4 | J13: 3 | K13: 4 | L13: 4 | M13: ある | P13: 第1期
A14: 45875.746 | B14: 1438 | C14: 中村円香 | D14: プロジェクトマネージャー実践研修 | E14: 永谷 裕子 (プロジェクトマネージャー実践研修担当) | F14: 4 | G14: 4 | H14: 4 | I14: 3 | J14: 4 | K14: 4 | L14: 4 | M14: ある | N14: 実践形式のテーマがわかりやすく、PMの経験がなくてもわかりやすかったです。 | O14: 話題が豊富で何に対しても回答していただけたので、話しやすかったです。 | P14: 第1期
A15: 45895.757 | B15: 1120 | C15: 辻隆範 | D15: フロントエンドエンジニア実践研修(React) 初級編 | E15: 日暮 香美 (フロントエンドエンジニア実践研修(React) 初級編、中級編担当) | F15: 3 | G15: 3 | H15: 3 | I15: 3 | J15: 2 | K15: 3 | L15: 3 | M15: 分からない | N15: 資料がどこまで含まれているのかわかりずらく、どこから自分である程度調べるべきなのか、これで進め方はあっているのかという不安があった | O15: 丁寧にご対応いただきありがたかったです。 | P15: 第1期
A16: 45895.797 | B16: 1180 | C16: 内藤宏治 | D16: フロントエンドエンジニア実践研修(React) 初級編 | E16: 日暮 香美 (フロントエンドエンジニア実践研修(React) 初級編、中級編担当) | F16: 2 | G16: 3 | H16: 3 | I16: 2 | J16: 1 | K16: 3 | L16: 3 | M16: ある | P16: 第1期
A17: 45898.565 | B17: 1343 | C17: 雪吉礼名 | D17: フロントエンドエンジニア実践研修(React) 中級編 | E17: 柴﨑 良平 (フロントエンドエンジニア実践研修(React) 中級編担当) | F17: 4 | G17: 3 | H17: 4 | I17: 3 | J17: 3 | K17: 4 | L17: 4 | M17: ある | N17: ReduxやSliceをほとんど知らなかったのでつまづくこともありましたが、調べながら進めることができました。 案件が落ち着いている時期だったので、今回は早めに提出ができました。 繁忙期と重なっていたら、課題をこなすのが難しかったかなと感じました。 | O17: 細かい点まで確認していただきありがとうございました。 | P17: 第1期
A18: 45902.745 | B18: 983 | C18: 田中辰弥 | D18: フロントエンドエンジニア実践研修(React) 初級編 | E18: 伊藤 健一 (フロントエンドエンジニア実践研修(React) 初級編担当) | F18: 2 | G18: 3 | H18: 3 | I18: 3 | J18: 2 | K18: 2 | L18: 2 | M18: 分からない | N18: 研修課題が誤記がわりとあったり、問題の内容がわかりづらいところがあったので、もう少し問題内容を正確に作成して頂きたいと思いました。 | P18: 第1期
A19: 45904.462 | B19: 001475 | C19: Joao Henrique Hideki Shirata | D19: クラウドインフラエンジニア実践研修(AWS) 初級編 | E19: 天野 盛介 (クラウドインフラエンジニア実践研修(AWS) 初級編、中級編担当) | F19: 4 | G19: 4 | H19: 4 | I19: 4 | J19: 4 | K19: 4 | L19: 4 | M19: ある | P19: 第1期
A20: 45904.47 | B20: 1430 | C20: 佐々木淳 | D20: クラウドインフラエンジニア実践研修(AWS) 初級編 | E20: 天野 盛介 (クラウドインフラエンジニア実践研修(AWS) 初級編、中級編担当) | F20: 3 | G20: 3 | H20: 3 | I20: 3 | J20: 2 | K20: 3 | L20: 3 | M20: ある | N20: 学びがあり、受講して良かったです。なお、研修テキスト（手順書）についての意見が2点あります。1点目として、品質についてです。手順書の記載誤りにより、手順どおりにいかないところが複数あり、想定以上に時間がかかりました。配布前の確認が不足していると思われます。2点目は、記載内容として、要件と手順以外の記載が少ないため、理解度向上につながるようなTipsを増やすと尚良いと思いました。Tipsの例として、サービスのユースケース、方法が複数あるケースでそれぞれのメリット・デメリット、などです。 | O20: 丁寧にご対応をいただき、ありがとうございました。 | P20: 第1期
A21: 45904.789 | B21: 909 | C21: 緒方遼太郎 | D21: システムエンジニア実践研修 | E21: 大矢 和輝 (システムエンジニア実践研修担当) | F21: 4 | G21: 3 | H21: 4 | I21: 4 | J21: 4 | K21: 4 | L21: 4 | M21: 分からない | O21: 資料を読み込む時間が多くあった、印象なので、別日で事前に読み込める機会があればいいなと思いました。 | P21: 第1期
A22: 45904.789 | B22: 1296 | C22: 南川颯 | D22: システムエンジニア実践研修 | E22: 大矢 和輝 (システムエンジニア実践研修担当) | F22: 2 | G22: 2 | H22: 3 | I22: 3 | J22: 2 | K22: 3 | L22: 3 | M22: ある | P22: 第1期
A23: 45904.79 | B23: 1372 | C23: 本田詞音 | D23: システムエンジニア実践研修 | E23: 大矢 和輝 (システムエンジニア実践研修担当) | F23: 4 | G23: 4 | H23: 4 | I23: 4 | J23: 4 | K23: 4 | L23: 4 | M23: ある | O23: 資料も教え方も実践課題もすごく良く、ためになりました。 | P23: 第1期
A24: 45904.79 | B24: 315 | C24: 足立洋介 | D24: システムエンジニア実践研修 | E24: 大矢 和輝 (システムエンジニア実践研修担当) | F24: 3 | G24: 4 | H24: 3 | I24: 3 | J24: 3 | K24: 3 | L24: 4 | M24: ある | N24: DB定義や画面入力書などを業務上やっていた、見たことがあったため、新たな学びというより復習になる部分が多かった。ユーザー側の要件定義の部分は未知の部分のため経験からの話が大変ためになった。 | P24: 第1期
A25: 45904.79 | B25: 985 | C25: 宇山卓見 | D25: システムエンジニア実践研修 | E25: 大矢 和輝 (システムエンジニア実践研修担当) | F25: 1 | G25: 4 | H25: 2 | I25: 2 | J25: 2 | K25: 3 | L25: 4 | M25: ある | N25: 実業まで普段やっていることより難易度がかなり低く感じた（私にとっては当たり前のことがほとんどだった）。 | O25: 話し方はすごく分かりやすかったので、今回の内容を難しくて感じた方にはいい研修なのかなと思いました。 | P25: 第1期
A26: 45904.79 | B26: 1027 | C26: 畦﨑凜 | D26: システムエンジニア実践研修 | E26: 大矢 和輝 (システムエンジニア実践研修担当) | F26: 3 | G26: 3 | H26: 4 | I26: 3 | J26: 3 | K26: 3 | L26: 3 | M26: ある | P26: 第1期
A27: 45904.791 | B27: 1286 | C27: 古賀巧 | D27: システムエンジニア実践研修 | E27: 大矢 和輝 (システムエンジニア実践研修担当) | F27: 4 | G27: 4 | H27: 4 | I27: 4 | J27: 4 | K27: 4 | L27: 4 | M27: ある | N27: リモートではなく、集まって参加する意味があった。早起き成功してよかった。 頂いた資料がとても参考になったので見返したい。 | O27: リモートではなく、集まって参加する意味があった。早起き成功してよかった。 頂いた資料がとても参考になったので見返したい。 | P27: 第1期
A28: 45904.791 | B28: 001195 | C28: 木俣颯太 | D28: システムエンジニア実践研修 | E28: 大矢 和輝 (システムエンジニア実践研修担当) | F28: 3 | G28: 4 | H28: 4 | I28: 3 | J28: 4 | K28: 3 | L28: 1 | M28: 分からない | N28: 新しい知識の研修でとても勉強になりました。 普段の業務がインフラの運用が主なので今後アプリの設計書や用件定義書を読み込む際にどのような内容が記載あるのかが理解できました。 | P28: 第1期
A29: 45904.792 | B29: 001205 | C29: 佐藤夏実 | D29: システムエンジニア実践研修 | E29: 大矢 和輝 (システムエンジニア実践研修担当) | F29: 3 | G29: 3 | H29: 3 | I29: 3 | J29: 2 | K29: 3 | L29: 3 | M29: 分からない | N29: システムエンジニアの全体像がわかってよかった。あまり知識がなかったのでイーランニングもとてもためになった。イーランニング比べて目的がよくわからなかったらつまずきやすいところなどがまとめられたらよかったかと思った。後半は単純作業だと感じた。 | O29: 本日はありがとうございました。今後システムエンジニアの一部の仕事に関わることもあると思うので今日の経験を活かしたいとおもいました。ありがとうございます。 | P29: 第1期
A30: 45904.793 | B30: 001270 | C30: 山岸一範 | D30: システムエンジニア実践研修 | E30: 大矢 和輝 (システムエンジニア実践研修担当) | F30: 3 | G30: 4 | H30: 2 | I30: 2 | J30: 3 | K30: 3 | L30: 3 | M30: ある | N30: 要件定義、基本設計、詳細設計で作成するドキュメントで曖昧なものがあるので、このケースではこのフェーズで作る必要があるとかも教えて欲しかった。 手で設計書は普段書かないのでPCで書かせて欲しかった。 オンライン開催でPCで課題を各自でやって、出来上がった課題の成果物を画面共有で見せる方が効率がいいと思った。 | O30: 丁寧で質問に対しても詳しく答えてくださって、雰囲気はとてもよかった。 | P30: 第1期
A31: 45904.795 | B31: 1029 | C31: 大橋絵実 | D31: システムエンジニア実践研修 | E31: 大矢 和輝 (システムエンジニア実践研修担当) | F31: 2 | G31: 4 | H31: 2 | I31: 2 | J31: 1 | K31: 2 | L31: 4 | M31: ある | N31: 本日はありがとうございました。完全アナログだったため、より業務に近いように色んなツール等を用いながら学べるとより実践に活かせそうだなあと感じました。また、内容が広く浅くだったため、個人的にはDB設計や業務フローをより深く学びたかったです。 | P31: 第1期
A32: 45904.807 | B32: 001326 | C32: 吉田 優太 | D32: システムエンジニア実践研修 | E32: 大矢 和輝 (システムエンジニア実践研修担当) | F32: 4 | G32: 3 | H32: 4 | I32: 4 | J32: 4 | K32: 3 | L32: 4 | M32: ある | N32: この度は研修の機会をいただきありがとうございました。 今まで要件定義と基本設計を体系的に教わる機会が無かったので、とても有意義でした。 研修内容も現役で上流工程を担当されている方だったので、実務に即した形で大変参考になりました。 一つ要望がありまして、ワーク実施する際の様式が手書きでやりにくさを感じました。 早さと共有しやすさを考慮してPCでやらせてもらえるともっと良かったかなと思いました。 (講師の方も若干やりにくそうでした。。。) Google meetの画面共有を使えば個人単位での発表とかもやりやすそうなので、次期以降で検討もらえればと思います。 とはいえ、満足度は高かったです！ | O32: 今回のような形式での講義は初めてと伺っていましたが、そこまで違和感は無かったです。 段取り周りで若干不慣れな印象を抱きましたが、研修の質や満足度を著しく下げるような物ではなかったです。 スライド資料も読みやすく感じました。 要望としてはせっかく現役で上流やられている方なので、実務であった事をコラム的にもっと聞きたかったかもしれません。 | P32: 第1期
A33: 45908.373 | B33: 023007 | C33: 松永圭悟 | D33: フロントエンドエンジニア実践研修(React) 中級編 | E33: 松永 圭悟 (フロントエンドエンジニア実践研修(React) 初級編、中級編担当) | F33: 3 | G33: 2 | H33: 3 | I33: 2 | J33: 2 | K33: 2 | L33: 1 | M33: 分からない | N33: 提出物の締め切りタイミングを、より早めになるようにして頂ければと思います。 理由として、2日前の提出で確認がだいぶぎりぎりであった為です。 | P33: 第1期
A34: 45911.559 | B34: 737 | C34: 上地航平 | D34: クラウドインフラエンジニア実践研修(AWS) 中級編 | E34: 天野 盛介 (クラウドインフラエンジニア実践研修(AWS) 初級編、中級編担当) | F34: 4 | G34: 4 | H34: 4 | I34: 4 | J34: 4 | K34: 4 | L34: 4 | M34: ある | N34: 普段の担当業務の中では、すでに構築されたECSアプリケーションの開発保守をしています。今回の研修を受講し進めていくなかで構成図ベースでしかECSを理解していませんでしたが、コンソールを触っていくなかで構成図のクラスタはここのコンソール画面とリンクしているといったイメージがついたので、今後の業務（トラシュー）に活用できると感じています。 あと手順書は詳細にかかれており、詰まるところも少なくクオリティは高かったなと思いました。 （一部上手くいかない箇所がありましたが、そのトラシュー含めて勉強になりました。） | O34: 成果物に対する適切なレビューと今後の改修に向けたヒアリングをして頂いたのが良かったです。今後上級コースの新規開設や既存の初級・中級の拡充にも期待しています。 | P34: 第1期
A35: 45911.57 | B35: 1433 | C35: 黒岩勇哉 | D35: クラウドインフラエンジニア実践研修(AWS) 中級編 | E35: 天野 盛介 (クラウドインフラエンジニア実践研修(AWS) 初級編、中級編担当) | F35: 3 | G35: 4 | H35: 4 | I35: 4 | J35: 3 | K35: 3 | L35: 4 | M35: ある | P35: 第1期
A36: 45911.719 | B36: 1172 | C36: 秋山悠 | D36: クラウドインフラエンジニア実践研修(AWS) 初級編 | E36: 天野 盛介 (クラウドインフラエンジニア実践研修(AWS) 初級編、中級編担当) | F36: 3 | G36: 4 | H36: 4 | I36: 3 | J36: 3 | K36: 4 | L36: 4 | M36: ある | P36: 第1期
A37: 45912.638 | B37: 1307 | C37: 中澤勇志 | D37: クラウドインフラエンジニア実践研修(GC) 中級編 | E37: 野川 錦策 (クラウドインフラエンジニア実践研修(GC) 初級編、中級編担当) | F37: 4 | G37: 4 | H37: 3 | I37: 3 | J37: 3 | K37: 3 | L37: 3 | M37: ある | P37: 第1期
A38: 45912.66 | B38: 01124 | C38: 寺田 侃生 | D38: クラウドインフラエンジニア実践研修(GC) 中級編 | E38: 野川 錦策 (クラウドインフラエンジニア実践研修(GC) 初級編、中級編担当) | F38: 4 | G38: 4 | H38: 4 | I38: 3 | J38: 4 | K38: 4 | L38: 4 | M38: ある | N38: 難易度は高いと感じたが達成感を得られてよかった | O38: 特にありません | P38: 第1期
A39: 45912.739 | B39: 150 | C39: 上地佑弥 | D39: プロジェクトマネージャー実践研修 | E39: 永谷 裕子 (プロジェクトマネージャー実践研修担当) | F39: 4 | G39: 4 | H39: 4 | I39: 4 | J39: 4 | K39: 4 | L39: 4 | M39: ある | P39: 第1期
A40: 45912.739 | B40: 742 | C40: 櫻田博之 | D40: プロジェクトマネージャー実践研修 | E40: 永谷 裕子 (プロジェクトマネージャー実践研修担当) | F40: 4 | G40: 4 | H40: 4 | I40: 4 | J40: 4 | K40: 4 | L40: 4 | M40: ある | P40: 第1期
...

Sheet ピボット テーブル
A1: 受講時期 | B1: 第1期
G2: 研修名 | H2: 理解できていない | I2: 理解できている | J2: 十分に理解できている | K2: 総計
A3: COUNTA of 氏名 | B3: ② 研修内容は理解出来ましたか？（全く理解出来ていない：1、理解出来ていない：2、理解出来ている：3、十分に理解出来ている：4） | G3: クラウドインフラエンジニア実践研修(AWS) 初級編 | I3: 3 | J3: 3 | K3: 6
A4: 研修名 | B4: 2 | C4: 3 | D4: 4 | E4: 総計 | G4: クラウドインフラエンジニア実践研修(AWS) 中級編 | I4: 4 | J4: 6 | K4: 10
A5: クラウドインフラエンジニア実践研修(AWS) 初級編 | C5: 3 | D5: 3 | E5: 6 | G5: クラウドインフラエンジニア実践研修(GC) 初級編 | H5: 2 | I5: 1 | K5: 3
A6: クラウドインフラエンジニア実践研修(AWS) 中級編 | C6: 4 | D6: 6 | E6: 10 | G6: クラウドインフラエンジニア実践研修(GC) 中級編 | J6: 3 | K6: 3
A7: クラウドインフラエンジニア実践研修(GC) 初級編 | B7: 2 | C7: 1 | E7: 3 | G7: システムエンジニア実践研修 | H7: 1 | I7: 4 | J7: 7 | K7: 12
A8: クラウドインフラエンジニア実践研修(GC) 中級編 | D8: 3 | E8: 3 | G8: スマホアプリエンジニア実践研修 初級編 | I8: 1 | J8: 1 | K8: 2
A9: システムエンジニア実践研修 | B9: 1 | C9: 4 | D9: 7 | E9: 12 | G9: スマホアプリエンジニア実践研修 中級編 | J9: 1 | K9: 1
A10: スマホアプリエンジニア実践研修 初級編 | C10: 1 | D10: 1 | E10: 2 | G10: プロジェクトマネージャー実践研修 | I10: 6 | J10: 21 | K10: 27
A11: スマホアプリエンジニア実践研修 中級編 | D11: 1 | E11: 1 | G11: フロントエンドエンジニア実践研修(React) 初級編 | I11: 5 | J11: 1 | K11: 6
A12: プロジェクトマネージャー実践研修 | C12: 6 | D12: 21 | E12: 27 | G12: フロントエンドエンジニア実践研修(React) 中級編 | H12: 1 | I12: 4 | J12: 7 | K12: 12
A13: フロントエンドエンジニア実践研修(React) 初級編 | C13: 5 | D13: 1 | E13: 6 | G13: フロントエンドエンジニア実践研修(Vue.js) 初級編 | I13: 2 | J13: 2 | K13: 4
A14: フロントエンドエンジニア実践研修(React) 中級編 | B14: 1 | C14: 4 | D14: 7 | E14: 12 | G14: フロントエンドエンジニア実践研修(Vue.js) 中級編 | J14: 1 | K14: 1
A15: フロントエンドエンジニア実践研修(Vue.js) 初級編 | C15: 2 | D15: 2 | E15: 4 | G15: 総計 | H15: 4 | I15: 30 | J15: 53 | K15: 87
A16: フロントエンドエンジニア実践研修(Vue.js) 中級編 | D16: 1 | E16: 1
A17: 総計 | B17: 4 | C17: 30 | D17: 53 | E17: 87

Sheet アンケート集計
A1: 基本情報 | C1: アンケート集計
A2: コース名 | B2: 受講者数 | C2: 研修満足度 | D2: 研修必要度 | E2: 研修理解度 | F2: 講師評価 | G2: 教材評価
A3: プロジェクトマネージャー実践研修 | B3: =IFERROR(COUNTIF(中間データ!$D:$D, $A3), "") -> 36 | C3: =IFERROR(AVERAGEIFS(中間データ!$F:$F, 中間データ!$D:$D, $A3), "") -> 3.9166667 | D3: =IFERROR(AVERAGEIFS(中間データ!$H:$H, 中間データ!$D:$D, $A3), "") -> 3.9444444 | E3: =IFERROR(AVERAGEIFS(中間データ!$G:$G, 中間データ!$D:$D, $A3), "") -> 3.8055556 | F3: =IFERROR(AVERAGEIFS(中間データ!$K:$K, 中間データ!$D:$D, $A3), "") -> 3.8333333 | G3: =IFERROR(AVERAGEIFS(中間データ!$J:$J, 中間データ!$D:$D, $A3), "") -> 3.6388889
A4: システムエンジニア実践研修 | B4: =IFERROR(COUNTIF(中間データ!$D:$D, $A4), "") -> 12 | C4: =IFERROR(AVERAGEIFS(中間データ!$F:$F, 中間データ!$D:$D, $A4), "") -> 3 | D4: =IFERROR(AVERAGEIFS(中間データ!$H:$H, 中間データ!$D:$D, $A4), "") -> 3.25 | E4: =IFERROR(AVERAGEIFS(中間データ!$G:$G, 中間データ!$D:$D, $A4), "") -> 3.5 | F4: =IFERROR(AVERAGEIFS(中間データ!$K:$K, 中間データ!$D:$D, $A4), "") -> 3.1666667 | G4: =IFERROR(AVERAGEIFS(中間データ!$J:$J, 中間データ!$D:$D, $A4), "") -> 3
A5: スマホアプリエンジニア実践研修 初級編 | B5: =IFERROR(COUNTIF(中間データ!$D:$D, $A5), "") -> 3 | C5: =IFERROR(AVERAGEIFS(中間データ!$F:$F, 中間データ!$D:$D, $A5), "") -> 3.6666667 | D5: =IFERROR(AVERAGEIFS(中間データ!$H:$H, 中間データ!$D:$D, $A5), "") -> 3.6666667 | E5: =IFERROR(AVERAGEIFS(中間データ!$G:$G, 中間データ!$D:$D, $A5), "") -> 3.3333333 | F5: =IFERROR(AVERAGEIFS(中間データ!$K:$K, 中間データ!$D:$D, $A5), "") -> 3.6666667 | G5: =IFERROR(AVERAGEIFS(中間データ!$J:$J, 中間データ!$D:$D, $A5), "") -> 3
A6: スマホアプリエンジニア実践研修 中級編 | B6: =IFERROR(COUNTIF(中間データ!$D:$D, $A6), "") -> 1 | C6: =IFERROR(AVERAGEIFS(中間データ!$F:$F, 中間データ!$D:$D, $A6), "") -> 4 | D6: =IFERROR(AVERAGEIFS(中間データ!$H:$H, 中間データ!$D:$D, $A6), "") -> 4 | E6: =IFERROR(AVERAGEIFS(中間データ!$G:$G, 中間データ!$D:$D, $A6), "") -> 4 | F6: =IFERROR(AVERAGEIFS(中間データ!$K:$K, 中間データ!$D:$D, $A6), "") -> 4 | G6: =IFERROR(AVERAGEIFS(中間データ!$J:$J, 中間データ!$D:$D, $A6), "") -> 4
A7: バックエンドエンジニア実践研修(Python) 初級編 | B7: =IFERROR(COUNTIF(中間データ!$D:$D, $A7), "") -> 1 | C7: =IFERROR(AVERAGEIFS(中間データ!$F:$F, 中間データ!$D:$D, $A7), "") -> 3 | D7: =IFERROR(AVERAGEIFS(中間データ!$H:$H, 中間データ!$D:$D, $A7), "") -> 3 | E7: =IFERROR(AVERAGEIFS(中間データ!$G:$G, 中間データ!$D:$D, $A7), "") -> 2 | F7: =IFERROR(AVERAGEIFS(中間データ!$K:$K, 中間データ!$D:$D, $A7), "") -> 4 | G7: =IFERROR(AVERAGEIFS(中間データ!$J:$J, 中間データ!$D:$D, $A7), "") -> 3
A8: バックエンドエンジニア実践研修(Python) 中級編 | B8: =IFERROR(COUNTIF(中間データ!$D:$D, $A8), "") -> 0 | C8: =IFERROR(AVERAGEIFS(中間データ!$F:$F, 中間データ!$D:$D, $A8), "") | D8: =IFERROR(AVERAGEIFS(中間データ!$H:$H, 中間データ!$D:$D, $A8), "") | E8: =IFERROR(AVERAGEIFS(中間データ!$G:$G, 中間データ!$D:$D, $A8), "") | F8: =IFERROR(AVERAGEIFS(中間データ!$K:$K, 中間データ!$D:$D, $A8), "") | G8: =IFERROR(AVERAGEIFS(中間データ!$J:$J, 中間データ!$D:$D, $A8), "")
A9: バックエンドエンジニア実践研修(PHP) 初級編 | B9: =IFERROR(COUNTIF(中間データ!$D:$D, $A9), "") -> 1 | C9: =IFERROR(AVERAGEIFS(中間データ!$F:$F, 中間データ!$D:$D, $A9), "") -> 4 | D9: =IFERROR(AVERAGEIFS(中間データ!$H:$H, 中間データ!$D:$D, $A9), "") -> 4 | E9: =IFERROR(AVERAGEIFS(中間データ!$G:$G, 中間データ!$D:$D, $A9), "") -> 3 | F9: =IFERROR(AVERAGEIFS(中間データ!$K:$K, 中間データ!$D:$D, $A9), "") -> 4 | G9: =IFERROR(AVERAGEIFS(中間データ!$J:$J, 中間データ!$D:$D, $A9), "") -> 4
A10: バックエンドエンジニア実践研修(PHP) 中級編 | B10: =IFERROR(COUNTIF(中間データ!$D:$D, $A10), "") -> 1 | C10: =IFERROR(AVERAGEIFS(中間データ!$F:$F, 中間データ!$D:$D, $A10), "") -> 3 | D10: =IFERROR(AVERAGEIFS(中間データ!$H:$H, 中間データ!$D:$D, $A10), "") -> 3 | E10: =IFERROR(AVERAGEIFS(中間データ!$G:$G, 中間データ!$D:$D, $A10), "") -> 4 | F10: =IFERROR(AVERAGEIFS(中間データ!$K:$K, 中間データ!$D:$D, $A10), "") -> 4 | G10: =IFERROR(AVERAGEIFS(中間データ!$J:$J, 中間データ!$D:$D, $A10), "") -> 3
A11: フロントエンドエンジニア実践研修(Vue.js) 初級編 | B11: =IFERROR(COUNTIF(中間データ!$D:$D, $A11), "") -> 5 | C11: =IFERROR(AVERAGEIFS(中間データ!$F:$F, 中間データ!$D:$D, $A11), "") -> 3.4 | D11: =IFERROR(AVERAGEIFS(中間データ!$H:$H, 中間データ!$D:$D, $A11), "") -> 3.8 | E11: =IFERROR(AVERAGEIFS(中間データ!$G:$G, 中間データ!$D:$D, $A11), "") -> 3.4 | F11: =IFERROR(AVERAGEIFS(中間データ!$K:$K, 中間データ!$D:$D, $A11), "") -> 3.8 | G11: =IFERROR(AVERAGEIFS(中間データ!$J:$J, 中間データ!$D:$D, $A11), "") -> 3.8
A12: フロントエンドエンジニア実践研修(Vue.js) 中級編 | B12: =IFERROR(COUNTIF(中間データ!$D:$D, $A12), "") -> 2 | C12: =IFERROR(AVERAGEIFS(中間データ!$F:$F, 中間データ!$D:$D, $A12), "") -> 2.5 | D12: =IFERROR(AVERAGEIFS(中間データ!$H:$H, 中間データ!$D:$D, $A12), "") -> 2.5 | E12: =IFERROR(AVERAGEIFS(中間データ!$G:$G, 中間データ!$D:$D, $A12), "") -> 3.5 | F12: =IFERROR(AVERAGEIFS(中間データ!$K:$K, 中間データ!$D:$D, $A12), "") -> 2.5 | G12: =IFERROR(AVERAGEIFS(中間データ!$J:$J, 中間データ!$D:$D, $A12), "") -> 3
A13: フロントエンドエンジニア実践研修(React) 初級編 | B13: =IFERROR(COUNTIF(中間データ!$D:$D, $A13), "") -> 12 | C13: =IFERROR(AVERAGEIFS(中間データ!$F:$F, 中間データ!$D:$D, $A13), "") -> 3.25 | D13: =IFERROR(AVERAGEIFS(中間データ!$H:$H, 中間データ!$D:$D, $A13), "") -> 3.5 | E13: =IFERROR(AVERAGEIFS(中間データ!$G:$G, 中間データ!$D:$D, $A13), "") -> 3.4166667 | F13: =IFERROR(AVERAGEIFS(中間データ!$K:$K, 中間データ!$D:$D, $A13), "") -> 3.3333333 | G13: =IFERROR(AVERAGEIFS(中間データ!$J:$J, 中間データ!$D:$D, $A13), "") -> 2.9166667
A14: フロントエンドエンジニア実践研修(React) 中級編 | B14: =IFERROR(COUNTIF(中間データ!$D:$D, $A14), "") -> 19 | C14: =IFERROR(AVERAGEIFS(中間データ!$F:$F, 中間データ!$D:$D, $A14), "") -> 3.5789474 | D14: =IFERROR(AVERAGEIFS(中間データ!$H:$H, 中間データ!$D:$D, $A14), "") -> 3.6315789 | E14: =IFERROR(AVERAGEIFS(中間データ!$G:$G, 中間データ!$D:$D, $A14), "") -> 3.4210526 | F14: =IFERROR(AVERAGEIFS(中間データ!$K:$K, 中間データ!$D:$D, $A14), "") -> 3.4210526 | G14: =IFERROR(AVERAGEIFS(中間データ!$J:$J, 中間データ!$D:$D, $A14), "") -> 3.2105263
... A18: クラウドインフラエンジニア実践研修(AWS) 中級編 | B18: =IFERROR(COUNTIF(中間データ!$D:$D, $A18), "") -> 19 | C18: =IFERROR(AVERAGEIFS(中間データ!$F:$F, 中間データ!$D:$D, $A18), "") -> 3.4210526 | D18: =IFERROR(AVERAGEIFS(中間データ!$H:$H, 中間データ!$D:$D, $A18), "") -> 3.5789474 | E18: =IFERROR(AVERAGEIFS(中間データ!$G:$G, 中間データ!$D:$D, $A18), "") -> 3.6315789 | F18: =IFERROR(AVERAGEIFS(中間データ!$K:$K, 中間データ!$D:$D, $A18), "") -> 3.2631579 | G18: =IFERROR(AVERAGEIFS(中間データ!$J:$J, 中間データ!$D:$D, $A18), "") -> 2.8421053
C19: =IFERROR(AVERAGEIFS(中間データ!$F:$F, 中間データ!$D:$D, $A19), "") -> 0 | D19: =IFERROR(AVERAGEIFS(中間データ!$H:$H, 中間データ!$D:$D, $A19), "") -> 0 | E19: =IFERROR(AVERAGEIFS(中間データ!$G:$G, 中間データ!$D:$D, $A19), "") -> 0 | F19: =IFERROR(AVERAGEIFS(中間データ!$K:$K, 中間データ!$D:$D, $A19), "") -> 0 | G19: =IFERROR(AVERAGEIFS(中間データ!$J:$J, 中間データ!$D:$D, $A19), "") -> 0
C20: =IFERROR(AVERAGEIFS(中間データ!$F:$F, 中間データ!$D:$D, $A20), "") -> 0 | D20: =IFERROR(AVERAGEIFS(中間データ!$H:$H, 中間データ!$D:$D, $A20), "") -> 0 | E20: =IFERROR(AVERAGEIFS(中間データ!$G:$G, 中間データ!$D:$D, $A20), "") -> 0 | F20: =IFERROR(AVERAGEIFS(中間データ!$K:$K, 中間データ!$D:$D, $A20), "") -> 0 | G20: =IFERROR(AVERAGEIFS(中間データ!$J:$J, 中間データ!$D:$D, $A20), "") -> 0
C21: =IFERROR(AVERAGEIFS(中間データ!$F:$F, 中間データ!$D:$D, $A21), "") -> 0 | D21: =IFERROR(AVERAGEIFS(中間データ!$H:$H, 中間データ!$D:$D, $A21), "") -> 0 | E21: =IFERROR(AVERAGEIFS(中間データ!$G:$G, 中間データ!$D:$D, $A21), "") -> 0 | F21: =IFERROR(AVERAGEIFS(中間データ!$K:$K, 中間データ!$D:$D, $A21), "") -> 0 | G21: =IFERROR(AVERAGEIFS(中間データ!$J:$J, 中間データ!$D:$D, $A21), "") -> 0
C22: =IFERROR(AVERAGEIFS(中間データ!$F:$F, 中間データ!$D:$D, $A22), "") -> 0 | D22: =IFERROR(AVERAGEIFS(中間データ!$H:$H, 中間データ!$D:$D, $A22), "") -> 0 | E22: =IFERROR(AVERAGEIFS(中間データ!$G:$G, 中間データ!$D:$D, $A22), "") -> 0 | F22: =IFERROR(AVERAGEIFS(中間データ!$K:$K, 中間データ!$D:$D, $A22), "") -> 0 | G22: =IFERROR(AVERAGEIFS(中間データ!$J:$J, 中間データ!$D:$D, $A22), "") -> 0
C23: =IFERROR(AVERAGEIFS(中間データ!$F:$F, 中間データ!$D:$D, $A23), "") -> 0 | D23: =IFERROR(AVERAGEIFS(中間データ!$H:$H, 中間データ!$D:$D, $A23), "") -> 0 | E23: =IFERROR(AVERAGEIFS(中間データ!$G:$G, 中間データ!$D:$D, $A23), "") -> 0 | F23: =IFERROR(AVERAGEIFS(中間データ!$K:$K, 中間データ!$D:$D, $A23), "") -> 0 | G23: =IFERROR(AVERAGEIFS(中間データ!$J:$J, 中間データ!$D:$D, $A23), "") -> 0
C24: =IFERROR(AVERAGEIFS(中間データ!$F:$F, 中間データ!$D:$D, $A24), "") -> 0 | D24: =IFERROR(AVERAGEIFS(中間データ!$H:$H, 中間データ!$D:$D, $A24), "") -> 0 | E24: =IFERROR(AVERAGEIFS(中間データ!$G:$G, 中間データ!$D:$D, $A24), "") -> 0 | F24: =IFERROR(AVERAGEIFS(中間データ!$K:$K, 中間データ!$D:$D, $A24), "") -> 0 | G24: =IFERROR(AVERAGEIFS(中間データ!$J:$J, 中間データ!$D:$D, $A24), "") -> 0

Sheet 中間データ
A1: {=アンケート結果!A:O} -> タイムスタンプ | B1: 社員番号 | C1: 氏名 | D1: 研修名をお選び下さい。 | E1: 担当した講師名をお選び下さい。 | F1: ① 研修に満足しましたか？（全く思わない：1、思わない：2、思う：3、強く思う：4） | G1: ② 研修内容は理解出来ましたか？（全く理解出来ていない：1、理解出来ていない：2、理解出来ている：3、十分に理解出来ている：4） | H1: ③ 研修で新たな学びは得られましたか？または必要な知識は得られましたか？（全く得られていない：1、得られていない：2、得られている：3、十分に得られている：4） | I1: ④ 研修内容のボリュームは適切でしたか？（全く適切ではない：1、適切ではない：2、適切である：3、十分に適切である：4） | J1: ⑤ 研修のテキスト、教材に対して満足しましたか？（全く思わない：1、思わない：2、思う：3、強く思う：4） | K1: ⑥ 講師の講義、あるいはフィードバックに対して満足しましたか？（全く思わない：1、思わない：2、思う：3、強く思う：4） | L1: ⑦ 講師は研修内容に関する知識を持っていましたか ？（全く持っていない：1、持っていない：2、持っている：3、十分に持っている：4） | M1: ⑧ 今回の研修で学んだことを、今後の業務で実践する機会はありそうですか？ | N1: ⑨ 研修に対する感想や要望などあれば、自由にご記入下さい。 | O1: ➉ 講師に対する感想や要望などあれば、自由にご記入下さい。 | P1: 日付
A2: 45875.741 | B2: 586 | C2: 鈴木 健斗 | D2: プロジェクトマネージャー実践研修 | E2: 永谷 裕子 (プロジェクトマネージャー実践研修担当) | F2: 4 | G2: 4 | H2: 4 | I2: 4 | J2: 4 | K2: 4 | L2: 4 | M2: ある | N2: 0 | O2: 0 | P2: =IF(A2="", "", INT(A2)) -> 45875
A3: 45875.741 | B3: 1295 | C3: 望月洋平 | D3: プロジェクトマネージャー実践研修 | E3: 永谷 裕子 (プロジェクトマネージャー実践研修担当) | F3: 4 | G3: 4 | H3: 4 | I3: 3 | J3: 3 | K3: 3 | L3: 4 | M3: ある | N3: 座学より演習時間を増やしてほしい | O3: 0 | P3: =IF(A3="", "", INT(A3)) -> 45875
A4: 45875.742 | B4: 1117 | C4: 廣田慎太郎 | D4: プロジェクトマネージャー実践研修 | E4: 永谷 裕子 (プロジェクトマネージャー実践研修担当) | F4: 4 | G4: 4 | H4: 4 | I4: 4 | J4: 4 | K4: 4 | L4: 4 | M4: ある | N4: PCを利用しない形式なので良かった。→PC利用するとどうしても仕事をしてしまう場面があるため。 ワークの題材について、引越じゃなく、具体的なIT関連PJにしても良かったと思う(参加者が全員IT経験者のため) | O4: 所々で体験談を挟んでいただいた点が良かったです。ありがとうごさいました。 | P4: =IF(A4="", "", INT(A4)) -> 45875
A5: 45875.742 | B5: 604 | C5: 田中弘紀 | D5: プロジェクトマネージャー実践研修 | E5: 永谷 裕子 (プロジェクトマネージャー実践研修担当) | F5: 3 | G5: 4 | H5: 4 | I5: 4 | J5: 3 | K5: 3 | L5: 4 | M5: ある | N5: 模造紙に手書きでは無く、スプレッドシートやスライドなどで実習に取り組めたら やりやすいと感じました。 | O5: 0 | P5: =IF(A5="", "", INT(A5)) -> 45875
A6: 45875.742 | B6: 1350 | C6: 齋藤ダイキ | D6: プロジェクトマネージャー実践研修 | E6: 永谷 裕子 (プロジェクトマネージャー実践研修担当) | F6: 4 | G6: 3 | H6: 4 | I6: 4 | J6: 4 | K6: 4 | L6: 4 | M6: ある | N6: PMでは無いので、PMがどのようなことを考えて業務を行なっているか学びながら体験できてとても良かった | O6: 実務を行なっていた講師なので、踏み込んだ話を聞けたし、いろいろ話ししてくれて楽しい研修だなと感じた | P6: =IF(A6="", "", INT(A6)) -> 45875
A7: 45875.742 | B7: 1140 | C7: 長谷川 裕昭 | D7: プロジェクトマネージャー実践研修 | E7: 永谷 裕子 (プロジェクトマネージャー実践研修担当) | F7: 4 | G7: 4 | H7: 3 | I7: 4 | J7: 4 | K7: 3 | L7: 4 | M7: ある | N7: PMとしてどうするべきか、何をするべきか、何を考えるべきかなど、学び考えることができ非常にいい経験になりました。 | O7: 0 | P7: =IF(A7="", "", INT(A7)) -> 45875
A8: 45875.742 | B8: 367 | C8: 小谷大基 | D8: プロジェクトマネージャー実践研修 | E8: 永谷 裕子 (プロジェクトマネージャー実践研修担当) | F8: 4 | G8: 4 | H8: 4 | I8: 4 | J8: 4 | K8: 4 | L8: 4 | M8: ある | N8: PM目指すかどうか関係無くプロジェクト進行についての大事な知識が詰まっているのでうちのエンジニアが全員受けるべきだと思いました。 | O8: 永谷先生の説明は非常に分かりやすく、自己学習でわからなかった点がクリアになってよかったです。 | P8: =IF(A8="", "", INT(A8)) -> 45875
A9: 45875.743 | B9: 1315 | C9: 小畑アリス | D9: プロジェクトマネージャー実践研修 | E9: 永谷 裕子 (プロジェクトマネージャー実践研修担当) | F9: 4 | G9: 4 | H9: 4 | I9: 4 | J9: 4 | K9: 4 | L9: 4 | M9: ある | N9: ワークがたくさんあり楽しかったです。実際に現在担当しているプロジェクトで不安に思ってることや解決策とかを学べました。仕事から離れて対面でやる勉強会はオンラインよりたくさん吸収できたように思います。ありがとうございました。 | O9: ２日間ありがとうございました。いつもワークの発表をした際に、みんなの意見に対して、いいね！と褒めてくださったのがすごく印象的でしたし、日々のMTGで私も真似しようと思いました。pmbokは、本が分厚くて勉強する気にならなかったので、対面でワークたくさんで勉強できたのはすごくありがたかったです。ありがとうございました。これから、PM頑張ります。 | P9: =IF(A9="", "", INT(A9)) -> 45875
A10: 45875.743 | B10: 494 | C10: 阿部幸司 | D10: プロジェクトマネージャー実践研修 | E10: 永谷 裕子 (プロジェクトマネージャー実践研修担当) | F10: 4 | G10: 4 | H10: 4 | I10: 3 | J10: 4 | K10: 4 | L10: 4 | M10: ある | N10: 漠然と知っていたことを体系として知れてよかったです。短い時間の中で要点を押さえての研修だったと思うのでまだまだ奥深いと思っているので復習と自己学習、アウトプットをして忘れないようにしていきたいとおもいます。 | O10: 実際の経験からのお話があってより現場を感じられてよかったです。 | P10: =IF(A10="", "", INT(A10)) -> 45875
A11: 45875.744 | B11: 1332 | C11: 江端隼樹 | D11: プロジェクトマネージャー実践研修 | E11: 永谷 裕子 (プロジェクトマネージャー実践研修担当) | F11: 4 | G11: 4 | H11: 4 | I11: 4 | J11: 4 | K11: 4 | L11: 4 | M11: ある | N11: 今まではっきりとPMという形で参画したプロジェクトはなかったが、WBSの作成やガントチャートは自分なりに作っていた。 ハードスキルは知っていることもあったが、ソフトスキルは知らないことも多かったので、これから身につけたい | O11: 永谷さんの経験もたくさん話してくださり、参考になりました | P11: =IF(A11="", "", INT(A11)) -> 45875
A12: 45875.744 | B12: 345 | C12: 謝花 彰一 | D12: プロジェクトマネージャー実践研修 | E12: 永谷 裕子 (プロジェクトマネージャー実践研修担当) | F12: 4 | G12: 3 | H12: 4 | I12: 3 | J12: 2 | K12: 4 | L12: 4 | M12: ある | N12: 実践パートがもう少し多ければいいかなと思いました。 | O12: 色々な自身の経験談があり楽しく進められた、マネジメントに対する知識も凄いなと思いました。 | P12: =IF(A12="", "", INT(A12)) -> 45875
A13: 45875.745 | B13: 1152 | C13: 片山健太郎 | D13: プロジェクトマネージャー実践研修 | E13: 永谷 裕子 (プロジェクトマネージャー実践研修担当) | F13: 4 | G13: 3 | H13: 4 | I13: 4 | J13: 3 | K13: 4 | L13: 4 | M13: ある | N13: 0 | O13: 0 | P13: =IF(A13="", "", INT(A13)) -> 45875
A14: 45875.746 | B14: 1438 | C14: 中村円香 | D14: プロジェクトマネージャー実践研修 | E14: 永谷 裕子 (プロジェクトマネージャー実践研修担当) | F14: 4 | G14: 4 | H14: 4 | I14: 3 | J14: 4 | K14: 4 | L14: 4 | M14: ある | N14: 実践形式のテーマがわかりやすく、PMの経験がなくてもわかりやすかったです。 | O14: 話題が豊富で何に対しても回答していただけたので、話しやすかったです。 | P14: =IF(A14="", "", INT(A14)) -> 45875
A15: 45895.757 | B15: 1120 | C15: 辻隆範 | D15: フロントエンドエンジニア実践研修(React) 初級編 | E15: 日暮 香美 (フロントエンドエンジニア実践研修(React) 初級編、中級編担当) | F15: 3 | G15: 3 | H15: 3 | I15: 3 | J15: 2 | K15: 3 | L15: 3 | M15: 分からない | N15: 資料がどこまで含まれているのかわかりずらく、どこから自分である程度調べるべきなのか、これで進め方はあっているのかという不安があった | O15: 丁寧にご対応いただきありがたかったです。 | P15: =IF(A15="", "", INT(A15)) -> 45895
A16: 45895.797 | B16: 1180 | C16: 内藤宏治 | D16: フロントエンドエンジニア実践研修(React) 初級編 | E16: 日暮 香美 (フロントエンドエンジニア実践研修(React) 初級編、中級編担当) | F16: 2 | G16: 3 | H16: 3 | I16: 2 | J16: 1 | K16: 3 | L16: 3 | M16: ある | N16: 0 | O16: 0 | P16: =IF(A16="", "", INT(A16)) -> 45895
A17: 45898.565 | B17: 1343 | C17: 雪吉礼名 | D17: フロントエンドエンジニア実践研修(React) 中級編 | E17: 柴﨑 良平 (フロントエンドエンジニア実践研修(React) 中級編担当) | F17: 4 | G17: 3 | H17: 4 | I17: 3 | J17: 3 | K17: 4 | L17: 4 | M17: ある | N17: ReduxやSliceをほとんど知らなかったのでつまづくこともありましたが、調べながら進めることができました。 案件が落ち着いている時期だったので、今回は早めに提出ができました。 繁忙期と重なっていたら、課題をこなすのが難しかったかなと感じました。 | O17: 細かい点まで確認していただきありがとうございました。 | P17: =IF(A17="", "", INT(A17)) -> 45898
A18: 45902.745 | B18: 983 | C18: 田中辰弥 | D18: フロントエンドエンジニア実践研修(React) 初級編 | E18: 伊藤 健一 (フロントエンドエンジニア実践研修(React) 初級編担当) | F18: 2 | G18: 3 | H18: 3 | I18: 3 | J18: 2 | K18: 2 | L18: 2 | M18: 分からない | N18: 研修課題が誤記がわりとあったり、問題の内容がわかりづらいところがあったので、もう少し問題内容を正確に作成して頂きたいと思いました。 | O18: 0 | P18: =IF(A18="", "", INT(A18)) -> 45902
A19: 45904.462 | B19: 001475 | C19: Joao Henrique Hideki Shirata | D19: クラウドインフラエンジニア実践研修(AWS) 初級編 | E19: 天野 盛介 (クラウドインフラエンジニア実践研修(AWS) 初級編、中級編担当) | F19: 4 | G19: 4 | H19: 4 | I19: 4 | J19: 4 | K19: 4 | L19: 4 | M19: ある | N19: 0 | O19: 0 | P19: =IF(A19="", "", INT(A19)) -> 45904
A20: 45904.47 | B20: 1430 | C20: 佐々木淳 | D20: クラウドインフラエンジニア実践研修(AWS) 初級編 | E20: 天野 盛介 (クラウドインフラエンジニア実践研修(AWS) 初級編、中級編担当) | F20: 3 | G20: 3 | H20: 3 | I20: 3 | J20: 2 | K20: 3 | L20: 3 | M20: ある | N20: 学びがあり、受講して良かったです。なお、研修テキスト（手順書）についての意見が2点あります。1点目として、品質についてです。手順書の記載誤りにより、手順どおりにいかないところが複数あり、想定以上に時間がかかりました。配布前の確認が不足していると思われます。2点目は、記載内容として、要件と手順以外の記載が少ないため、理解度向上につながるようなTipsを増やすと尚良いと思いました。Tipsの例として、サービスのユースケース、方法が複数あるケースでそれぞれのメリット・デメリット、などです。 | O20: 丁寧にご対応をいただき、ありがとうございました。 | P20: =IF(A20="", "", INT(A20)) -> 45904
A21: 45904.789 | B21: 909 | C21: 緒方遼太郎 | D21: システムエンジニア実践研修 | E21: 大矢 和輝 (システムエンジニア実践研修担当) | F21: 4 | G21: 3 | H21: 4 | I21: 4 | J21: 4 | K21: 4 | L21: 4 | M21: 分からない | N21: 0 | O21: 資料を読み込む時間が多くあった、印象なので、別日で事前に読み込める機会があればいいなと思いました。 | P21: =IF(A21="", "", INT(A21)) -> 45904
A22: 45904.789 | B22: 1296 | C22: 南川颯 | D22: システムエンジニア実践研修 | E22: 大矢 和輝 (システムエンジニア実践研修担当) | F22: 2 | G22: 2 | H22: 3 | I22: 3 | J22: 2 | K22: 3 | L22: 3 | M22: ある | N22: 0 | O22: 0 | P22: =IF(A22="", "", INT(A22)) -> 45904
A23: 45904.79 | B23: 1372 | C23: 本田詞音 | D23: システムエンジニア実践研修 | E23: 大矢 和輝 (システムエンジニア実践研修担当) | F23: 4 | G23: 4 | H23: 4 | I23: 4 | J23: 4 | K23: 4 | L23: 4 | M23: ある | N23: 0 | O23: 資料も教え方も実践課題もすごく良く、ためになりました。 | P23: =IF(A23="", "", INT(A23)) -> 45904
A24: 45904.79 | B24: 315 | C24: 足立洋介 | D24: システムエンジニア実践研修 | E24: 大矢 和輝 (システムエンジニア実践研修担当) | F24: 3 | G24: 4 | H24: 3 | I24: 3 | J24: 3 | K24: 3 | L24: 4 | M24: ある | N24: DB定義や画面入力書などを業務上やっていた、見たことがあったため、新たな学びというより復習になる部分が多かった。ユーザー側の要件定義の部分は未知の部分のため経験からの話が大変ためになった。 | O24: 0 | P24: =IF(A24="", "", INT(A24)) -> 45904
A25: 45904.79 | B25: 985 | C25: 宇山卓見 | D25: システムエンジニア実践研修 | E25: 大矢 和輝 (システムエンジニア実践研修担当) | F25: 1 | G25: 4 | H25: 2 | I25: 2 | J25: 2 | K25: 3 | L25: 4 | M25: ある | N25: 実業まで普段やっていることより難易度がかなり低く感じた（私にとっては当たり前のことがほとんどだった）。 | O25: 話し方はすごく分かりやすかったので、今回の内容を難しくて感じた方にはいい研修なのかなと思いました。 | P25: =IF(A25="", "", INT(A25)) -> 45904
A26: 45904.79 | B26: 1027 | C26: 畦﨑凜 | D26: システムエンジニア実践研修 | E26: 大矢 和輝 (システムエンジニア実践研修担当) | F26: 3 | G26: 3 | H26: 4 | I26: 3 | J26: 3 | K26: 3 | L26: 3 | M26: ある | N26: 0 | O26: 0 | P26: =IF(A26="", "", INT(A26)) -> 45904
A27: 45904.791 | B27: 1286 | C27: 古賀巧 | D27: システムエンジニア実践研修 | E27: 大矢 和輝 (システムエンジニア実践研修担当) | F27: 4 | G27: 4 | H27: 4 | I27: 4 | J27: 4 | K27: 4 | L27: 4 | M27: ある | N27: リモートではなく、集まって参加する意味があった。早起き成功してよかった。 頂いた資料がとても参考になったので見返したい。 | O27: リモートではなく、集まって参加する意味があった。早起き成功してよかった。 頂いた資料がとても参考になったので見返したい。 | P27: =IF(A27="", "", INT(A27)) -> 45904
A28: 45904.791 | B28: 001195 | C28: 木俣颯太 | D28: システムエンジニア実践研修 | E28: 大矢 和輝 (システムエンジニア実践研修担当) | F28: 3 | G28: 4 | H28: 4 | I28: 3 | J28: 4 | K28: 3 | L28: 1 | M28: 分からない | N28: 新しい知識の研修でとても勉強になりました。 普段の業務がインフラの運用が主なので今後アプリの設計書や用件定義書を読み込む際にどのような内容が記載あるのかが理解できました。 | O28: 0 | P28: =IF(A28="", "", INT(A28)) -> 45904
A29: 45904.792 | B29: 001205 | C29: 佐藤夏実 | D29: システムエンジニア実践研修 | E29: 大矢 和輝 (システムエンジニア実践研修担当) | F29: 3 | G29: 3 | H29: 3 | I29: 3 | J29: 2 | K29: 3 | L29: 3 | M29: 分からない | N29: システムエンジニアの全体像がわかってよかった。あまり知識がなかったのでイーランニングもとてもためになった。イーランニング比べて目的がよくわからなかったらつまずきやすいところなどがまとめられたらよかったかと思った。後半は単純作業だと感じた。 | O29: 本日はありがとうございました。今後システムエンジニアの一部の仕事に関わることもあると思うので今日の経験を活かしたいとおもいました。ありがとうございます。 | P29: =IF(A29="", "", INT(A29)) -> 45904
A30: 45904.793 | B30: 001270 | C30: 山岸一範 | D30: システムエンジニア実践研修 | E30: 大矢 和輝 (システムエンジニア実践研修担当) | F30: 3 | G30: 4 | H30: 2 | I30: 2 | J30: 3 | K30: 3 | L30: 3 | M30: ある | N30: 要件定義、基本設計、詳細設計で作成するドキュメントで曖昧なものがあるので、このケースではこのフェーズで作る必要があるとかも教えて欲しかった。 手で設計書は普段書かないのでPCで書かせて欲しかった。 オンライン開催でPCで課題を各自でやって、出来上がった課題の成果物を画面共有で見せる方が効率がいいと思った。 | O30: 丁寧で質問に対しても詳しく答えてくださって、雰囲気はとてもよかった。 | P30: =IF(A30="", "", INT(A30)) -> 45904
A31: 45904.795 | B31: 1029 | C31: 大橋絵実 | D31: システムエンジニア実践研修 | E31: 大矢 和輝 (システムエンジニア実践研修担当) | F31: 2 | G31: 4 | H31: 2 | I31: 2 | J31: 1 | K31: 2 | L31: 4 | M31: ある | N31: 本日はありがとうございました。完全アナログだったため、より業務に近いように色んなツール等を用いながら学べるとより実践に活かせそうだなあと感じました。また、内容が広く浅くだったため、個人的にはDB設計や業務フローをより深く学びたかったです。 | O31: 0 | P31: =IF(A31="", "", INT(A31)) -> 45904
A32: 45904.807 | B32: 001326 | C32: 吉田 優太 | D32: システムエンジニア実践研修 | E32: 大矢 和輝 (システムエンジニア実践研修担当) | F32: 4 | G32: 3 | H32: 4 | I32: 4 | J32: 4 | K32: 3 | L32: 4 | M32: ある | N32: この度は研修の機会をいただきありがとうございました。 今まで要件定義と基本設計を体系的に教わる機会が無かったので、とても有意義でした。 研修内容も現役で上流工程を担当されている方だったので、実務に即した形で大変参考になりました。 一つ要望がありまして、ワーク実施する際の様式が手書きでやりにくさを感じました。 早さと共有しやすさを考慮してPCでやらせてもらえるともっと良かったかなと思いました。 (講師の方も若干やりにくそうでした。。。) Google meetの画面共有を使えば個人単位での発表とかもやりやすそうなので、次期以降で検討もらえればと思います。 とはいえ、満足度は高かったです！ | O32: 今回のような形式での講義は初めてと伺っていましたが、そこまで違和感は無かったです。 段取り周りで若干不慣れな印象を抱きましたが、研修の質や満足度を著しく下げるような物ではなかったです。 スライド資料も読みやすく感じました。 要望としてはせっかく現役で上流やられている方なので、実務であった事をコラム的にもっと聞きたかったかもしれません。 | P32: =IF(A32="", "", INT(A32)) -> 45904
A33: 45908.373 | B33: 023007 | C33: 松永圭悟 | D33: フロントエンドエンジニア実践研修(React) 中級編 | E33: 松永 圭悟 (フロントエンドエンジニア実践研修(React) 初級編、中級編担当) | F33: 3 | G33: 2 | H33: 3 | I33: 2 | J33: 2 | K33: 2 | L33: 1 | M33: 分からない | N33: 提出物の締め切りタイミングを、より早めになるようにして頂ければと思います。 理由として、2日前の提出で確認がだいぶぎりぎりであった為です。 | O33: 0 | P33: =IF(A33="", "", INT(A33)) -> 45908
A34: 45911.559 | B34: 737 | C34: 上地航平 | D34: クラウドインフラエンジニア実践研修(AWS) 中級編 | E34: 天野 盛介 (クラウドインフラエンジニア実践研修(AWS) 初級編、中級編担当) | F34: 4 | G34: 4 | H34: 4 | I34: 4 | J34: 4 | K34: 4 | L34: 4 | M34: ある | N34: 普段の担当業務の中では、すでに構築されたECSアプリケーションの開発保守をしています。今回の研修を受講し進めていくなかで構成図ベースでしかECSを理解していませんでしたが、コンソールを触っていくなかで構成図のクラスタはここのコンソール画面とリンクしているといったイメージがついたので、今後の業務（トラシュー）に活用できると感じています。 あと手順書は詳細にかかれており、詰まるところも少なくクオリティは高かったなと思いました。 （一部上手くいかない箇所がありましたが、そのトラシュー含めて勉強になりました。） | O34: 成果物に対する適切なレビューと今後の改修に向けたヒアリングをして頂いたのが良かったです。今後上級コースの新規開設や既存の初級・中級の拡充にも期待しています。 | P34: =IF(A34="", "", INT(A34)) -> 45911
A35: 45911.57 | B35: 1433 | C35: 黒岩勇哉 | D35: クラウドインフラエンジニア実践研修(AWS) 中級編 | E35: 天野 盛介 (クラウドインフラエンジニア実践研修(AWS) 初級編、中級編担当) | F35: 3 | G35: 4 | H35: 4 | I35: 4 | J35: 3 | K35: 3 | L35: 4 | M35: ある | N35: 0 | O35: 0 | P35: =IF(A35="", "", INT(A35)) -> 45911
A36: 45911.719 | B36: 1172 | C36: 秋山悠 | D36: クラウドインフラエンジニア実践研修(AWS) 初級編 | E36: 天野 盛介 (クラウドインフラエンジニア実践研修(AWS) 初級編、中級編担当) | F36: 3 | G36: 4 | H36: 4 | I36: 3 | J36: 3 | K36: 4 | L36: 4 | M36: ある | N36: 0 | O36: 0 | P36: =IF(A36="", "", INT(A36)) -> 45911
A37: 45912.638 | B37: 1307 | C37: 中澤勇志 | D37: クラウドインフラエンジニア実践研修(GC) 中級編 | E37: 野川 錦策 (クラウドインフラエンジニア実践研修(GC) 初級編、中級編担当) | F37: 4 | G37: 4 | H37: 3 | I37: 3 | J37: 3 | K37: 3 | L37: 3 | M37: ある | N37: 0 | O37: 0 | P37: =IF(A37="", "", INT(A37)) -> 45912
A38: 45912.66 | B38: 01124 | C38: 寺田 侃生 | D38: クラウドインフラエンジニア実践研修(GC) 中級編 | E38: 野川 錦策 (クラウドインフラエンジニア実践研修(GC) 初級編、中級編担当) | F38: 4 | G38: 4 | H38: 4 | I38: 3 | J38: 4 | K38: 4 | L38: 4 | M38: ある | N38: 難易度は高いと感じたが達成感を得られてよかった | O38: 特にありません | P38: =IF(A38="", "", INT(A38)) -> 45912
A39: 45912.739 | B39: 150 | C39: 上地佑弥 | D39: プロジェクトマネージャー実践研修 | E39: 永谷 裕子 (プロジェクトマネージャー実践研修担当) | F39: 4 | G39: 4 | H39: 4 | I39: 4 | J39: 4 | K39: 4 | L39: 4 | M39: ある | N39: 0 | O39: 0 | P39: =IF(A39="", "", INT(A39)) -> 45912
A40: 45912.739 | B40: 742 | C40: 櫻田博之 | D40: プロジェクトマネージャー実践研修 | E40: 永谷 裕子 (プロジェクトマネージャー実践研修担当) | F40: 4 | G40: 4 | H40: 4 | I40: 4 | J40: 4 | K40: 4 | L40: 4 | M40: ある | N40: 0 | O40: 0 | P40: =IF(A40="", "", INT(A40)) -> 45912
...

Sheet 2025年度第1期_アンケート集計
A1: 基本情報 | C1: アンケート集計
A2: コース名 | B2: 回答者数 | C2: 研修満足度 | D2: 研修必要度 | E2: 研修理解度 | F2: 講師評価 | G2: 教材評価
A3: プロジェクトマネージャー実践研修 | B3: =IFERROR(COUNTIFS(中間データ!$D:$D,$A3,中間データ!$P:$P,">="&DATE(2025,8,1),中間データ!$P:$P,"<="&DATE(2025,10,31)),"") -> 27 | C3: =IFERROR(AVERAGEIFS(中間データ!$F:$F,中間データ!$D:$D,$A3,中間データ!$P:$P,">="&DATE(2025,8,1),中間データ!$P:$P,"<="&DATE(2025,10,31)),"") -> 3.9259259 | D3: =IFERROR(AVERAGEIFS(中間データ!$H:$H,中間データ!$D:$D,$A3,中間データ!$P:$P,">="&DATE(2025,8,1),中間データ!$P:$P,"<="&DATE(2025,10,31)),"") -> 3.9259259 | E3: =IFERROR(AVERAGEIFS(中間データ!$G:$G,中間データ!$D:$D,$A3,中間データ!$P:$P,">="&DATE(2025,8,1),中間データ!$P:$P,"<="&DATE(2025,10,31)),"") -> 3.7777778 | F3: =IFERROR(AVERAGEIFS(中間データ!$K:$K,中間データ!$D:$D,$A3,中間データ!$P:$P,">="&DATE(2025,8,1),中間データ!$P:$P,"<="&DATE(2025,10,31)),"") -> 3.8148148 | G3: =IFERROR(AVERAGEIFS(中間データ!$J:$J,中間データ!$D:$D,$A3,中間データ!$P:$P,">="&DATE(2025,8,1),中間データ!$P:$P,"<="&DATE(2025,10,31)),"") -> 3.6296296
A4: システムエンジニア実践研修 | B4: =IFERROR(COUNTIFS(中間データ!$D:$D,$A4,中間データ!$P:$P,">="&DATE(2025,8,1),中間データ!$P:$P,"<="&DATE(2025,10,31)),"") -> 12 | C4: =IFERROR(AVERAGEIFS(中間データ!$F:$F,中間データ!$D:$D,$A4,中間データ!$P:$P,">="&DATE(2025,8,1),中間データ!$P:$P,"<="&DATE(2025,10,31)),"") -> 3 | D4: =IFERROR(AVERAGEIFS(中間データ!$H:$H,中間データ!$D:$D,$A4,中間データ!$P:$P,">="&DATE(2025,8,1),中間データ!$P:$P,"<="&DATE(2025,10,31)),"") -> 3.25 | E4: =IFERROR(AVERAGEIFS(中間データ!$G:$G,中間データ!$D:$D,$A4,中間データ!$P:$P,">="&DATE(2025,8,1),中間データ!$P:$P,"<="&DATE(2025,10,31)),"") -> 3.5 | F4: =IFERROR(AVERAGEIFS(中間データ!$K:$K,中間データ!$D:$D,$A4,中間データ!$P:$P,">="&DATE(2025,8,1),中間データ!$P:$P,"<="&DATE(2025,10,31)),"") -> 3.1666667 | G4: =IFERROR(AVERAGEIFS(中間データ!$J:$J,中間データ!$D:$D,$A4,中間データ!$P:$P,">="&DATE(2025,8,1),中間データ!$P:$P,"<="&DATE(2025,10,31)),"") -> 3
A5: スマホアプリエンジニア実践研修 初級編 | B5: =IFERROR(COUNTIFS(中間データ!$D:$D,$A5,中間データ!$P:$P,">="&DATE(2025,8,1),中間データ!$P:$P,"<="&DATE(2025,10,31)),"") -> 2 | C5: =IFERROR(AVERAGEIFS(中間データ!$F:$F,中間データ!$D:$D,$A5,中間データ!$P:$P,">="&DATE(2025,8,1),中間データ!$P:$P,"<="&DATE(2025,10,31)),"") -> 3.5 | D5: =IFERROR(AVERAGEIFS(中間データ!$H:$H,中間データ!$D:$D,$A5,中間データ!$P:$P,">="&DATE(2025,8,1),中間データ!$P:$P,"<="&DATE(2025,10,31)),"") -> 3.5 | E5: =IFERROR(AVERAGEIFS(中間データ!$G:$G,中間データ!$D:$D,$A5,中間データ!$P:$P,">="&DATE(2025,8,1),中間データ!$P:$P,"<="&DATE(2025,10,31)),"") -> 3.5 | F5: =IFERROR(AVERAGEIFS(中間データ!$K:$K,中間データ!$D:$D,$A5,中間データ!$P:$P,">="&DATE(2025,8,1),中間データ!$P:$P,"<="&DATE(2025,10,31)),"") -> 3.5 | G5: =IFERROR(AVERAGEIFS(中間データ!$J:$J,中間データ!$D:$D,$A5,中間データ!$P:$P,">="&DATE(2025,8,1),中間データ!$P:$P,"<="&DATE(2025,10,31)),"") -> 2.5
A6: スマホアプリエンジニア実践研修 中級編 | B6: =IFERROR(COUNTIFS(中間データ!$D:$D,$A6,中間データ!$P:$P,">="&DATE(2025,8,1),中間データ!$P:$P,"<="&DATE(2025,10,31)),"") -> 1 | C6: =IFERROR(AVERAGEIFS(中間データ!$F:$F,中間データ!$D:$D,$A6,中間データ!$P:$P,">="&DATE(2025,8,1),中間データ!$P:$P,"<="&DATE(2025,10,31)),"") -> 4 | D6: =IFERROR(AVERAGEIFS(中間データ!$H:$H,中間データ!$D:$D,$A6,中間データ!$P:$P,">="&DATE(2025,8,1),中間データ!$P:$P,"<="&DATE(2025,10,31)),"") -> 4 | E6: =IFERROR(AVERAGEIFS(中間データ!$G:$G,中間データ!$D:$D,$A6,中間データ!$P:$P,">="&DATE(2025,8,1),中間データ!$P:$P,"<="&DATE(2025,10,31)),"") -> 4 | F6: =IFERROR(AVERAGEIFS(中間データ!$K:$K,中間データ!$D:$D,$A6,中間データ!$P:$P,">="&DATE(2025,8,1),中間データ!$P:$P,"<="&DATE(2025,10,31)),"") -> 4 | G6: =IFERROR(AVERAGEIFS(中間データ!$J:$J,中間データ!$D:$D,$A6,中間データ!$P:$P,">="&DATE(2025,8,1),中間データ!$P:$P,"<="&DATE(2025,10,31)),"") -> 4
A7: バックエンドエンジニア実践研修(Python) 初級編 | B7: =IFERROR(COUNTIFS(中間データ!$D:$D,$A7,中間データ!$P:$P,">="&DATE(2025,8,1),中間データ!$P:$P,"<="&DATE(2025,10,31)),"") -> 0 | C7: =IFERROR(AVERAGEIFS(中間データ!$F:$F,中間データ!$D:$D,$A7,中間データ!$P:$P,">="&DATE(2025,8,1),中間データ!$P:$P,"<="&DATE(2025,10,31)),"") | D7: =IFERROR(AVERAGEIFS(中間データ!$H:$H,中間データ!$D:$D,$A7,中間データ!$P:$P,">="&DATE(2025,8,1),中間データ!$P:$P,"<="&DATE(2025,10,31)),"") | E7: =IFERROR(AVERAGEIFS(中間データ!$G:$G,中間データ!$D:$D,$A7,中間データ!$P:$P,">="&DATE(2025,8,1),中間データ!$P:$P,"<="&DATE(2025,10,31)),"") | F7: =IFERROR(AVERAGEIFS(中間データ!$K:$K,中間データ!$D:$D,$A7,中間データ!$P:$P,">="&DATE(2025,8,1),中間データ!$P:$P,"<="&DATE(2025,10,31)),"") | G7: =IFERROR(AVERAGEIFS(中間データ!$J:$J,中間データ!$D:$D,$A7,中間データ!$P:$P,">="&DATE(2025,8,1),中間データ!$P:$P,"<="&DATE(2025,10,31)),"")
A8: バックエンドエンジニア実践研修(Python) 中級編 | B8: =IFERROR(COUNTIFS(中間データ!$D:$D,$A8,中間データ!$P:$P,">="&DATE(2025,8,1),中間データ!$P:$P,"<="&DATE(2025,10,31)),"") -> 0 | C8: =IFERROR(AVERAGEIFS(中間データ!$F:$F,中間データ!$D:$D,$A8,中間データ!$P:$P,">="&DATE(2025,8,1),中間データ!$P:$P,"<="&DATE(2025,10,31)),"") | D8: =IFERROR(AVERAGEIFS(中間データ!$H:$H,中間データ!$D:$D,$A8,中間データ!$P:$P,">="&DATE(2025,8,1),中間データ!$P:$P,"<="&DATE(2025,10,31)),"") | E8: =IFERROR(AVERAGEIFS(中間データ!$G:$G,中間データ!$D:$D,$A8,中間データ!$P:$P,">="&DATE(2025,8,1),中間データ!$P:$P,"<="&DATE(2025,10,31)),"") | F8: =IFERROR(AVERAGEIFS(中間データ!$K:$K,中間データ!$D:$D,$A8,中間データ!$P:$P,">="&DATE(2025,8,1),中間データ!$P:$P,"<="&DATE(2025,10,31)),"") | G8: =IFERROR(AVERAGEIFS(中間データ!$J:$J,中間データ!$D:$D,$A8,中間データ!$P:$P,">="&DATE(2025,8,1),中間データ!$P:$P,"<="&DATE(2025,10,31)),"")
A9: バックエンドエンジニア実践研修(PHP) 初級編 | B9: =IFERROR(COUNTIFS(中間データ!$D:$D,$A9,中間データ!$P:$P,">="&DATE(2025,8,1),中間データ!$P:$P,"<="&DATE(2025,10,31)),"") -> 0 | C9: =IFERROR(AVERAGEIFS(中間データ!$F:$F,中間データ!$D:$D,$A9,中間データ!$P:$P,">="&DATE(2025,8,1),中間データ!$P:$P,"<="&DATE(2025,10,31)),"") | D9: =IFERROR(AVERAGEIFS(中間データ!$H:$H,中間データ!$D:$D,$A9,中間データ!$P:$P,">="&DATE(2025,8,1),中間データ!$P:$P,"<="&DATE(2025,10,31)),"") | E9: =IFERROR(AVERAGEIFS(中間データ!$G:$G,中間データ!$D:$D,$A9,中間データ!$P:$P,">="&DATE(2025,8,1),中間データ!$P:$P,"<="&DATE(2025,10,31)),"") | F9: =IFERROR(AVERAGEIFS(中間データ!$K:$K,中間データ!$D:$D,$A9,中間データ!$P:$P,">="&DATE(2025,8,1),中間データ!$P:$P,"<="&DATE(2025,10,31)),"") | G9: =IFERROR(AVERAGEIFS(中間データ!$J:$J,中間データ!$D:$D,$A9,中間データ!$P:$P,">="&DATE(2025,8,1),中間データ!$P:$P,"<="&DATE(2025,10,31)),"")
A10: フロントエンドエンジニア実践研修(Vue.js) 初級編 | B10: =IFERROR(COUNTIFS(中間データ!$D:$D,$A10,中間データ!$P:$P,">="&DATE(2025,8,1),中間データ!$P:$P,"<="&DATE(2025,10,31)),"") -> 4 | C10: =IFERROR(AVERAGEIFS(中間データ!$F:$F,中間データ!$D:$D,$A10,中間データ!$P:$P,">="&DATE(2025,8,1),中間データ!$P:$P,"<="&DATE(2025,10,31)),"") -> 3.5 | D10: =IFERROR(AVERAGEIFS(中間データ!$H:$H,中間データ!$D:$D,$A10,中間データ!$P:$P,">="&DATE(2025,8,1),中間データ!$P:$P,"<="&DATE(2025,10,31)),"") -> 3.75 | E10: =IFERROR(AVERAGEIFS(中間データ!$G:$G,中間データ!$D:$D,$A10,中間データ!$P:$P,">="&DATE(2025,8,1),中間データ!$P:$P,"<="&DATE(2025,10,31)),"") -> 3.5 | F10: =IFERROR(AVERAGEIFS(中間データ!$K:$K,中間データ!$D:$D,$A10,中間データ!$P:$P,">="&DATE(2025,8,1),中間データ!$P:$P,"<="&DATE(2025,10,31)),"") -> 3.75 | G10: =IFERROR(AVERAGEIFS(中間データ!$J:$J,中間データ!$D:$D,$A10,中間データ!$P:$P,">="&DATE(2025,8,1),中間データ!$P:$P,"<="&DATE(2025,10,31)),"") -> 4
A11: フロントエンドエンジニア実践研修(Vue.js) 中級編 | B11: =IFERROR(COUNTIFS(中間データ!$D:$D,$A11,中間データ!$P:$P,">="&DATE(2025,8,1),中間データ!$P:$P,"<="&DATE(2025,10,31)),"") -> 1 | C11: =IFERROR(AVERAGEIFS(中間データ!$F:$F,中間データ!$D:$D,$A11,中間データ!$P:$P,">="&DATE(2025,8,1),中間データ!$P:$P,"<="&DATE(2025,10,31)),"") -> 2 | D11: =IFERROR(AVERAGEIFS(中間データ!$H:$H,中間データ!$D:$D,$A11,中間データ!$P:$P,">="&DATE(2025,8,1),中間データ!$P:$P,"<="&DATE(2025,10,31)),"") -> 1 | E11: =IFERROR(AVERAGEIFS(中間データ!$G:$G,中間データ!$D:$D,$A11,中間データ!$P:$P,">="&DATE(2025,8,1),中間データ!$P:$P,"<="&DATE(2025,10,31)),"") -> 4 | F11: =IFERROR(AVERAGEIFS(中間データ!$K:$K,中間データ!$D:$D,$A11,中間データ!$P:$P,">="&DATE(2025,8,1),中間データ!$P:$P,"<="&DATE(2025,10,31)),"") -> 1 | G11: =IFERROR(AVERAGEIFS(中間データ!$J:$J,中間データ!$D:$D,$A11,中間データ!$P:$P,">="&DATE(2025,8,1),中間データ!$P:$P,"<="&DATE(2025,10,31)),"") -> 3
A12: フロントエンドエンジニア実践研修(React) 初級編 | B12: =IFERROR(COUNTIFS(中間データ!$D:$D,$A12,中間データ!$P:$P,">="&DATE(2025,8,1),中間データ!$P:$P,"<="&DATE(2025,10,31)),"") -> 6 | C12: =IFERROR(AVERAGEIFS(中間データ!$F:$F,中間データ!$D:$D,$A12,中間データ!$P:$P,">="&DATE(2025,8,1),中間データ!$P:$P,"<="&DATE(2025,10,31)),"") -> 2.8333333 | D12: =IFERROR(AVERAGEIFS(中間データ!$H:$H,中間データ!$D:$D,$A12,中間データ!$P:$P,">="&DATE(2025,8,1),中間データ!$P:$P,"<="&DATE(2025,10,31)),"") -> 3.3333333 | E12: =IFERROR(AVERAGEIFS(中間データ!$G:$G,中間データ!$D:$D,$A12,中間データ!$P:$P,">="&DATE(2025,8,1),中間データ!$P:$P,"<="&DATE(2025,10,31)),"") -> 3.1666667 | F12: =IFERROR(AVERAGEIFS(中間データ!$K:$K,中間データ!$D:$D,$A12,中間データ!$P:$P,">="&DATE(2025,8,1),中間データ!$P:$P,"<="&DATE(2025,10,31)),"") -> 3 | G12: =IFERROR(AVERAGEIFS(中間データ!$J:$J,中間データ!$D:$D,$A12,中間データ!$P:$P,">="&DATE(2025,8,1),中間データ!$P:$P,"<="&DATE(2025,10,31)),"") -> 2.1666667
A13: フロントエンドエンジニア実践研修(React) 中級編 | B13: =IFERROR(COUNTIFS(中間データ!$D:$D,$A13,中間データ!$P:$P,">="&DATE(2025,8,1),中間データ!$P:$P,"<="&DATE(2025,10,31)),"") -> 12 | C13: =IFERROR(AVERAGEIFS(中間データ!$F:$F,中間データ!$D:$D,$A13,中間データ!$P:$P,">="&DATE(2025,8,1),中間データ!$P:$P,"<="&DATE(2025,10,31)),"") -> 3.5833333 | D13: =IFERROR(AVERAGEIFS(中間データ!$H:$H,中間データ!$D:$D,$A13,中間データ!$P:$P,">="&DATE(2025,8,1),中間データ!$P:$P,"<="&DATE(2025,10,31)),"") -> 3.5 | E13: =IFERROR(AVERAGEIFS(中間データ!$G:$G,中間データ!$D:$D,$A13,中間データ!$P:$P,">="&DATE(2025,8,1),中間データ!$P:$P,"<="&DATE(2025,10,31)),"") -> 3.5 | F13: =IFERROR(AVERAGEIFS(中間データ!$K:$K,中間データ!$D:$D,$A13,中間データ!$P:$P,">="&DATE(2025,8,1),中間データ!$P:$P,"<="&DATE(2025,10,31)),"") -> 3.1666667 | G13: =IFERROR(AVERAGEIFS(中間データ!$J:$J,中間データ!$D:$D,$A13,中間データ!$P:$P,">="&DATE(2025,8,1),中間データ!$P:$P,"<="&DATE(2025,10,31)),"") -> 3.0833333
A14: クラウドインフラエンジニア実践研修(GC) 初級編 | B14: =IFERROR(COUNTIFS(中間データ!$D:$D,$A14,中間データ!$P:$P,">="&DATE(2025,8,1),中間データ!$P:$P,"<="&DATE(2025,10,31)),"") -> 3 | C14: =IFERROR(AVERAGEIFS(中間データ!$F:$F,中間データ!$D:$D,$A14,中間データ!$P:$P,">="&DATE(2025,8,1),中間データ!$P:$P,"<="&DATE(2025,10,31)),"") -> 3 | D14: =IFERROR(AVERAGEIFS(中間データ!$H:$H,中間データ!$D:$D,$A14,中間データ!$P:$P,">="&DATE(2025,8,1),中間データ!$P:$P,"<="&DATE(2025,10,31)),"") -> 2.6666667 | E14: =IFERROR(AVERAGEIFS(中間データ!$G:$G,中間データ!$D:$D,$A14,中間データ!$P:$P,">="&DATE(2025,8,1),中間データ!$P:$P,"<="&DATE(2025,10,31)),"") -> 2.3333333 | F14: =IFERROR(AVERAGEIFS(中間データ!$K:$K,中間データ!$D:$D,$A14,中間データ!$P:$P,">="&DATE(2025,8,1),中間データ!$P:$P,"<="&DATE(2025,10,31)),"") -> 3 | G14: =IFERROR(AVERAGEIFS(中間データ!$J:$J,中間データ!$D:$D,$A14,中間データ!$P:$P,">="&DATE(2025,8,1),中間データ!$P:$P,"<="&DATE(2025,10,31)),"") -> 1.6666667
... A17: クラウドインフラエンジニア実践研修(AWS) 中級編 | B17: =IFERROR(COUNTIFS(中間データ!$D:$D,$A17,中間データ!$P:$P,">="&DATE(2025,8,1),中間データ!$P:$P,"<="&DATE(2025,10,31)),"") -> 10 | C17: =IFERROR(AVERAGEIFS(中間データ!$F:$F,中間データ!$D:$D,$A17,中間データ!$P:$P,">="&DATE(2025,8,1),中間データ!$P:$P,"<="&DATE(2025,10,31)),"") -> 3.3 | D17: =IFERROR(AVERAGEIFS(中間データ!$H:$H,中間データ!$D:$D,$A17,中間データ!$P:$P,">="&DATE(2025,8,1),中間データ!$P:$P,"<="&DATE(2025,10,31)),"") -> 3.6 | E17: =IFERROR(AVERAGEIFS(中間データ!$G:$G,中間データ!$D:$D,$A17,中間データ!$P:$P,">="&DATE(2025,8,1),中間データ!$P:$P,"<="&DATE(2025,10,31)),"") -> 3.6 | F17: =IFERROR(AVERAGEIFS(中間データ!$K:$K,中間データ!$D:$D,$A17,中間データ!$P:$P,">="&DATE(2025,8,1),中間データ!$P:$P,"<="&DATE(2025,10,31)),"") -> 3.1 | G17: =IFERROR(AVERAGEIFS(中間データ!$J:$J,中間データ!$D:$D,$A17,中間データ!$P:$P,">="&DATE(2025,8,1),中間データ!$P:$P,"<="&DATE(2025,10,31)),"") -> 2.5
C18: =IFERROR(AVERAGEIFS(中間データ!$F:$F, 中間データ!$D:$D, $A18), "") -> 0 | D18: =IFERROR(AVERAGEIFS(中間データ!$H:$H, 中間データ!$D:$D, $A18), "") -> 0 | E18: =IFERROR(AVERAGEIFS(中間データ!$G:$G, 中間データ!$D:$D, $A18), "") -> 0 | F18: =IFERROR(AVERAGEIFS(中間データ!$K:$K, 中間データ!$D:$D, $A18), "") -> 0 | G18: =IFERROR(AVERAGEIFS(中間データ!$J:$J, 中間データ!$D:$D, $A18), "") -> 0
C19: =IFERROR(AVERAGEIFS(中間データ!$F:$F, 中間データ!$D:$D, $A19), "") -> 0 | D19: =IFERROR(AVERAGEIFS(中間データ!$H:$H, 中間データ!$D:$D, $A19), "") -> 0 | E19: =IFERROR(AVERAGEIFS(中間データ!$G:$G, 中間データ!$D:$D, $A19), "") -> 0 | F19: =IFERROR(AVERAGEIFS(中間データ!$K:$K, 中間データ!$D:$D, $A19), "") -> 0 | G19: =IFERROR(AVERAGEIFS(中間データ!$J:$J, 中間データ!$D:$D, $A19), "") -> 0
C20: =IFERROR(AVERAGEIFS(中間データ!$F:$F, 中間データ!$D:$D, $A20), "") -> 0 | D20: =IFERROR(AVERAGEIFS(中間データ!$H:$H, 中間データ!$D:$D, $A20), "") -> 0 | E20: =IFERROR(AVERAGEIFS(中間データ!$G:$G, 中間データ!$D:$D, $A20), "") -> 0 | F20: =IFERROR(AVERAGEIFS(中間データ!$K:$K, 中間データ!$D:$D, $A20), "") -> 0 | G20: =IFERROR(AVERAGEIFS(中間データ!$J:$J, 中間データ!$D:$D, $A20), "") -> 0
C21: =IFERROR(AVERAGEIFS(中間データ!$F:$F, 中間データ!$D:$D, $A21), "") -> 0 | D21: =IFERROR(AVERAGEIFS(中間データ!$H:$H, 中間データ!$D:$D, $A21), "") -> 0 | E21: =IFERROR(AVERAGEIFS(中間データ!$G:$G, 中間データ!$D:$D, $A21), "") -> 0 | F21: =IFERROR(AVERAGEIFS(中間データ!$K:$K, 中間データ!$D:$D, $A21), "") -> 0 | G21: =IFERROR(AVERAGEIFS(中間データ!$J:$J, 中間データ!$D:$D, $A21), "") -> 0
C22: =IFERROR(AVERAGEIFS(中間データ!$F:$F, 中間データ!$D:$D, $A22), "") -> 0 | D22: =IFERROR(AVERAGEIFS(中間データ!$H:$H, 中間データ!$D:$D, $A22), "") -> 0 | E22: =IFERROR(AVERAGEIFS(中間データ!$G:$G, 中間データ!$D:$D, $A22), "") -> 0 | F22: =IFERROR(AVERAGEIFS(中間データ!$K:$K, 中間データ!$D:$D, $A22), "") -> 0 | G22: =IFERROR(AVERAGEIFS(中間データ!$J:$J, 中間データ!$D:$D, $A22), "") -> 0
C23: =IFERROR(AVERAGEIFS(中間データ!$F:$F, 中間データ!$D:$D, $A23), "") -> 0 | D23: =IFERROR(AVERAGEIFS(中間データ!$H:$H, 中間データ!$D:$D, $A23), "") -> 0 | E23: =IFERROR(AVERAGEIFS(中間データ!$G:$G, 中間データ!$D:$D, $A23), "") -> 0 | F23: =IFERROR(AVERAGEIFS(中間データ!$K:$K, 中間データ!$D:$D, $A23), "") -> 0 | G23: =IFERROR(AVERAGEIFS(中間データ!$J:$J, 中間データ!$D:$D, $A23), "") -> 0

Sheet 2025年度第2期_アンケート集計
A1: 基本情報 | C1: アンケート集計
A2: コース名 | B2: 回答者数 | C2: 研修満足度 | D2: 研修必要度 | E2: 研修理解度 | F2: 講師評価 | G2: 教材評価
A3: プロジェクトマネージャー実践研修 | B3: =IFERROR(COUNTIFS(中間データ!$D:$D,$A3,中間データ!$P:$P,">="&DATE(2025,11,1),中間データ!$P:$P,"<="&DATE(2026,1,31)),"") -> 0 | C3: =IFERROR(AVERAGEIFS(中間データ!$F:$F,中間データ!$D:$D,$A3,中間データ!$P:$P,">="&DATE(2025,11,1),中間データ!$P:$P,"<="&DATE(2026,1,31)),"") | D3: =IFERROR(AVERAGEIFS(中間データ!$H:$H,中間データ!$D:$D,$A3,中間データ!$P:$P,">="&DATE(2025,11,1),中間データ!$P:$P,"<="&DATE(2026,1,31)),"") | E3: =IFERROR(AVERAGEIFS(中間データ!$G:$G,中間データ!$D:$D,$A3,中間データ!$P:$P,">="&DATE(2025,11,1),中間データ!$P:$P,"<="&DATE(2026,1,31)),"") | F3: =IFERROR(AVERAGEIFS(中間データ!$K:$K,中間データ!$D:$D,$A3,中間データ!$P:$P,">="&DATE(2025,11,1),中間データ!$P:$P,"<="&DATE(2026,1,31)),"") | G3: =IFERROR(AVERAGEIFS(中間データ!$J:$J,中間データ!$D:$D,$A3,中間データ!$P:$P,">="&DATE(2025,11,1),中間データ!$P:$P,"<="&DATE(2026,1,31)),"")
A4: システムエンジニア実践研修 | B4: =IFERROR(COUNTIFS(中間データ!$D:$D,$A4,中間データ!$P:$P,">="&DATE(2025,11,1),中間データ!$P:$P,"<="&DATE(2026,1,31)),"") -> 0 | C4: =IFERROR(AVERAGEIFS(中間データ!$F:$F,中間データ!$D:$D,$A4,中間データ!$P:$P,">="&DATE(2025,11,1),中間データ!$P:$P,"<="&DATE(2026,1,31)),"") | D4: =IFERROR(AVERAGEIFS(中間データ!$H:$H,中間データ!$D:$D,$A4,中間データ!$P:$P,">="&DATE(2025,11,1),中間データ!$P:$P,"<="&DATE(2026,1,31)),"") | E4: =IFERROR(AVERAGEIFS(中間データ!$G:$G,中間データ!$D:$D,$A4,中間データ!$P:$P,">="&DATE(2025,11,1),中間データ!$P:$P,"<="&DATE(2026,1,31)),"") | F4: =IFERROR(AVERAGEIFS(中間データ!$K:$K,中間データ!$D:$D,$A4,中間データ!$P:$P,">="&DATE(2025,11,1),中間データ!$P:$P,"<="&DATE(2026,1,31)),"") | G4: =IFERROR(AVERAGEIFS(中間データ!$J:$J,中間データ!$D:$D,$A4,中間データ!$P:$P,">="&DATE(2025,11,1),中間データ!$P:$P,"<="&DATE(2026,1,31)),"")
A5: スマホアプリエンジニア実践研修 初級編 | B5: =IFERROR(COUNTIFS(中間データ!$D:$D,$A5,中間データ!$P:$P,">="&DATE(2025,11,1),中間データ!$P:$P,"<="&DATE(2026,1,31)),"") -> 1 | C5: =IFERROR(AVERAGEIFS(中間データ!$F:$F,中間データ!$D:$D,$A5,中間データ!$P:$P,">="&DATE(2025,11,1),中間データ!$P:$P,"<="&DATE(2026,1,31)),"") -> 4 | D5: =IFERROR(AVERAGEIFS(中間データ!$H:$H,中間データ!$D:$D,$A5,中間データ!$P:$P,">="&DATE(2025,11,1),中間データ!$P:$P,"<="&DATE(2026,1,31)),"") -> 4 | E5: =IFERROR(AVERAGEIFS(中間データ!$G:$G,中間データ!$D:$D,$A5,中間データ!$P:$P,">="&DATE(2025,11,1),中間データ!$P:$P,"<="&DATE(2026,1,31)),"") -> 3 | F5: =IFERROR(AVERAGEIFS(中間データ!$K:$K,中間データ!$D:$D,$A5,中間データ!$P:$P,">="&DATE(2025,11,1),中間データ!$P:$P,"<="&DATE(2026,1,31)),"") -> 4 | G5: =IFERROR(AVERAGEIFS(中間データ!$J:$J,中間データ!$D:$D,$A5,中間データ!$P:$P,">="&DATE(2025,11,1),中間データ!$P:$P,"<="&DATE(2026,1,31)),"") -> 4
A6: スマホアプリエンジニア実践研修 中級編 | B6: =IFERROR(COUNTIFS(中間データ!$D:$D,$A6,中間データ!$P:$P,">="&DATE(2025,11,1),中間データ!$P:$P,"<="&DATE(2026,1,31)),"") -> 0 | C6: =IFERROR(AVERAGEIFS(中間データ!$F:$F,中間データ!$D:$D,$A6,中間データ!$P:$P,">="&DATE(2025,11,1),中間データ!$P:$P,"<="&DATE(2026,1,31)),"") | D6: =IFERROR(AVERAGEIFS(中間データ!$H:$H,中間データ!$D:$D,$A6,中間データ!$P:$P,">="&DATE(2025,11,1),中間データ!$P:$P,"<="&DATE(2026,1,31)),"") | E6: =IFERROR(AVERAGEIFS(中間データ!$G:$G,中間データ!$D:$D,$A6,中間データ!$P:$P,">="&DATE(2025,11,1),中間データ!$P:$P,"<="&DATE(2026,1,31)),"") | F6: =IFERROR(AVERAGEIFS(中間データ!$K:$K,中間データ!$D:$D,$A6,中間データ!$P:$P,">="&DATE(2025,11,1),中間データ!$P:$P,"<="&DATE(2026,1,31)),"") | G6: =IFERROR(AVERAGEIFS(中間データ!$J:$J,中間データ!$D:$D,$A6,中間データ!$P:$P,">="&DATE(2025,11,1),中間データ!$P:$P,"<="&DATE(2026,1,31)),"")
A7: バックエンドエンジニア実践研修(Python) 初級編 | B7: =IFERROR(COUNTIFS(中間データ!$D:$D,$A7,中間データ!$P:$P,">="&DATE(2025,11,1),中間データ!$P:$P,"<="&DATE(2026,1,31)),"") -> 1 | C7: =IFERROR(AVERAGEIFS(中間データ!$F:$F,中間データ!$D:$D,$A7,中間データ!$P:$P,">="&DATE(2025,11,1),中間データ!$P:$P,"<="&DATE(2026,1,31)),"") -> 3 | D7: =IFERROR(AVERAGEIFS(中間データ!$H:$H,中間データ!$D:$D,$A7,中間データ!$P:$P,">="&DATE(2025,11,1),中間データ!$P:$P,"<="&DATE(2026,1,31)),"") -> 3 | E7: =IFERROR(AVERAGEIFS(中間データ!$G:$G,中間データ!$D:$D,$A7,中間データ!$P:$P,">="&DATE(2025,11,1),中間データ!$P:$P,"<="&DATE(2026,1,31)),"") -> 2 | F7: =IFERROR(AVERAGEIFS(中間データ!$K:$K,中間データ!$D:$D,$A7,中間データ!$P:$P,">="&DATE(2025,11,1),中間データ!$P:$P,"<="&DATE(2026,1,31)),"") -> 4 | G7: =IFERROR(AVERAGEIFS(中間データ!$J:$J,中間データ!$D:$D,$A7,中間データ!$P:$P,">="&DATE(2025,11,1),中間データ!$P:$P,"<="&DATE(2026,1,31)),"") -> 3
A8: バックエンドエンジニア実践研修(Python) 中級編 | B8: =IFERROR(COUNTIFS(中間データ!$D:$D,$A8,中間データ!$P:$P,">="&DATE(2025,11,1),中間データ!$P:$P,"<="&DATE(2026,1,31)),"") -> 0 | C8: =IFERROR(AVERAGEIFS(中間データ!$F:$F,中間データ!$D:$D,$A8,中間データ!$P:$P,">="&DATE(2025,11,1),中間データ!$P:$P,"<="&DATE(2026,1,31)),"") | D8: =IFERROR(AVERAGEIFS(中間データ!$H:$H,中間データ!$D:$D,$A8,中間データ!$P:$P,">="&DATE(2025,11,1),中間データ!$P:$P,"<="&DATE(2026,1,31)),"") | E8: =IFERROR(AVERAGEIFS(中間データ!$G:$G,中間データ!$D:$D,$A8,中間データ!$P:$P,">="&DATE(2025,11,1),中間データ!$P:$P,"<="&DATE(2026,1,31)),"") | F8: =IFERROR(AVERAGEIFS(中間データ!$K:$K,中間データ!$D:$D,$A8,中間データ!$P:$P,">="&DATE(2025,11,1),中間データ!$P:$P,"<="&DATE(2026,1,31)),"") | G8: =IFERROR(AVERAGEIFS(中間データ!$J:$J,中間データ!$D:$D,$A8,中間データ!$P:$P,">="&DATE(2025,11,1),中間データ!$P:$P,"<="&DATE(2026,1,31)),"")
A9: バックエンドエンジニア実践研修(PHP) 初級編 | B9: =IFERROR(COUNTIFS(中間データ!$D:$D,$A9,中間データ!$P:$P,">="&DATE(2025,11,1),中間データ!$P:$P,"<="&DATE(2026,1,31)),"") -> 1 | C9: =IFERROR(AVERAGEIFS(中間データ!$F:$F,中間データ!$D:$D,$A9,中間データ!$P:$P,">="&DATE(2025,11,1),中間データ!$P:$P,"<="&DATE(2026,1,31)),"") -> 4 | D9: =IFERROR(AVERAGEIFS(中間データ!$H:$H,中間データ!$D:$D,$A9,中間データ!$P:$P,">="&DATE(2025,11,1),中間データ!$P:$P,"<="&DATE(2026,1,31)),"") -> 4 | E9: =IFERROR(AVERAGEIFS(中間データ!$G:$G,中間データ!$D:$D,$A9,中間データ!$P:$P,">="&DATE(2025,11,1),中間データ!$P:$P,"<="&DATE(2026,1,31)),"") -> 3 | F9: =IFERROR(AVERAGEIFS(中間データ!$K:$K,中間データ!$D:$D,$A9,中間データ!$P:$P,">="&DATE(2025,11,1),中間データ!$P:$P,"<="&DATE(2026,1,31)),"") -> 4 | G9: =IFERROR(AVERAGEIFS(中間データ!$J:$J,中間データ!$D:$D,$A9,中間データ!$P:$P,">="&DATE(2025,11,1),中間データ!$P:$P,"<="&DATE(2026,1,31)),"") -> 4
A10: バックエンドエンジニア実践研修(PHP) 中級編 | B10: =IFERROR(COUNTIFS(中間データ!$D:$D,$A10,中間データ!$P:$P,">="&DATE(2025,11,1),中間データ!$P:$P,"<="&DATE(2026,1,31)),"") -> 1 | C10: =IFERROR(AVERAGEIFS(中間データ!$F:$F,中間データ!$D:$D,$A10,中間データ!$P:$P,">="&DATE(2025,11,1),中間データ!$P:$P,"<="&DATE(2026,1,31)),"") -> 3 | D10: =IFERROR(AVERAGEIFS(中間データ!$H:$H,中間データ!$D:$D,$A10,中間データ!$P:$P,">="&DATE(2025,11,1),中間データ!$P:$P,"<="&DATE(2026,1,31)),"") -> 3 | E10: =IFERROR(AVERAGEIFS(中間データ!$G:$G,中間データ!$D:$D,$A10,中間データ!$P:$P,">="&DATE(2025,11,1),中間データ!$P:$P,"<="&DATE(2026,1,31)),"") -> 4 | F10: =IFERROR(AVERAGEIFS(中間データ!$K:$K,中間データ!$D:$D,$A10,中間データ!$P:$P,">="&DATE(2025,11,1),中間データ!$P:$P,"<="&DATE(2026,1,31)),"") -> 4 | G10: =IFERROR(AVERAGEIFS(中間データ!$J:$J,中間データ!$D:$D,$A10,中間データ!$P:$P,">="&DATE(2025,11,1),中間データ!$P:$P,"<="&DATE(2026,1,31)),"") -> 3
A11: フロントエンドエンジニア実践研修(Vue.js) 初級編 | B11: =IFERROR(COUNTIFS(中間データ!$D:$D,$A11,中間データ!$P:$P,">="&DATE(2025,11,1),中間データ!$P:$P,"<="&DATE(2026,1,31)),"") -> 1 | C11: =IFERROR(AVERAGEIFS(中間データ!$F:$F,中間データ!$D:$D,$A11,中間データ!$P:$P,">="&DATE(2025,11,1),中間データ!$P:$P,"<="&DATE(2026,1,31)),"") -> 3 | D11: =IFERROR(AVERAGEIFS(中間データ!$H:$H,中間データ!$D:$D,$A11,中間データ!$P:$P,">="&DATE(2025,11,1),中間データ!$P:$P,"<="&DATE(2026,1,31)),"") -> 4 | E11: =IFERROR(AVERAGEIFS(中間データ!$G:$G,中間データ!$D:$D,$A11,中間データ!$P:$P,">="&DATE(2025,11,1),中間データ!$P:$P,"<="&DATE(2026,1,31)),"") -> 3 | F11: =IFERROR(AVERAGEIFS(中間データ!$K:$K,中間データ!$D:$D,$A11,中間データ!$P:$P,">="&DATE(2025,11,1),中間データ!$P:$P,"<="&DATE(2026,1,31)),"") -> 4 | G11: =IFERROR(AVERAGEIFS(中間データ!$J:$J,中間データ!$D:$D,$A11,中間データ!$P:$P,">="&DATE(2025,11,1),中間データ!$P:$P,"<="&DATE(2026,1,31)),"") -> 3
A12: フロントエンドエンジニア実践研修(Vue.js) 中級編 | B12: =IFERROR(COUNTIFS(中間データ!$D:$D,$A12,中間データ!$P:$P,">="&DATE(2025,11,1),中間データ!$P:$P,"<="&DATE(2026,1,31)),"") -> 1 | C12: =IFERROR(AVERAGEIFS(中間データ!$F:$F,中間データ!$D:$D,$A12,中間データ!$P:$P,">="&DATE(2025,11,1),中間データ!$P:$P,"<="&DATE(2026,1,31)),"") -> 3 | D12: =IFERROR(AVERAGEIFS(中間データ!$H:$H,中間データ!$D:$D,$A12,中間データ!$P:$P,">="&DATE(2025,11,1),中間データ!$P:$P,"<="&DATE(2026,1,31)),"") -> 4 | E12: =IFERROR(AVERAGEIFS(中間データ!$G:$G,中間データ!$D:$D,$A12,中間データ!$P:$P,">="&DATE(2025,11,1),中間データ!$P:$P,"<="&DATE(2026,1,31)),"") -> 3 | F12: =IFERROR(AVERAGEIFS(中間データ!$K:$K,中間データ!$D:$D,$A12,中間データ!$P:$P,">="&DATE(2025,11,1),中間データ!$P:$P,"<="&DATE(2026,1,31)),"") -> 4 | G12: =IFERROR(AVERAGEIFS(中間データ!$J:$J,中間データ!$D:$D,$A12,中間データ!$P:$P,">="&DATE(2025,11,1),中間データ!$P:$P,"<="&DATE(2026,1,31)),"") -> 3
A13: フロントエンドエンジニア実践研修(React) 初級編 | B13: =IFERROR(COUNTIFS(中間データ!$D:$D,$A13,中間データ!$P:$P,">="&DATE(2025,11,1),中間データ!$P:$P,"<="&DATE(2026,1,31)),"") -> 3 | C13: =IFERROR(AVERAGEIFS(中間データ!$F:$F,中間データ!$D:$D,$A13,中間データ!$P:$P,">="&DATE(2025,11,1),中間データ!$P:$P,"<="&DATE(2026,1,31)),"") -> 3.6666667 | D13: =IFERROR(AVERAGEIFS(中間データ!$H:$H,中間データ!$D:$D,$A13,中間データ!$P:$P,">="&DATE(2025,11,1),中間データ!$P:$P,"<="&DATE(2026,1,31)),"") -> 3.6666667 | E13: =IFERROR(AVERAGEIFS(中間データ!$G:$G,中間データ!$D:$D,$A13,中間データ!$P:$P,">="&DATE(2025,11,1),中間データ!$P:$P,"<="&DATE(2026,1,31)),"") -> 3.6666667 | F13: =IFERROR(AVERAGEIFS(中間データ!$K:$K,中間データ!$D:$D,$A13,中間データ!$P:$P,">="&DATE(2025,11,1),中間データ!$P:$P,"<="&DATE(2026,1,31)),"") -> 3.6666667 | G13: =IFERROR(AVERAGEIFS(中間データ!$J:$J,中間データ!$D:$D,$A13,中間データ!$P:$P,">="&DATE(2025,11,1),中間データ!$P:$P,"<="&DATE(2026,1,31)),"") -> 3.6666667
A14: フロントエンドエンジニア実践研修(React) 中級編 | B14: =IFERROR(COUNTIFS(中間データ!$D:$D,$A14,中間データ!$P:$P,">="&DATE(2025,11,1),中間データ!$P:$P,"<="&DATE(2026,1,31)),"") -> 6 | C14: =IFERROR(AVERAGEIFS(中間データ!$F:$F,中間データ!$D:$D,$A14,中間データ!$P:$P,">="&DATE(2025,11,1),中間データ!$P:$P,"<="&DATE(2026,1,31)),"") -> 3.6666667 | D14: =IFERROR(AVERAGEIFS(中間データ!$H:$H,中間データ!$D:$D,$A14,中間データ!$P:$P,">="&DATE(2025,11,1),中間データ!$P:$P,"<="&DATE(2026,1,31)),"") -> 3.8333333 | E14: =IFERROR(AVERAGEIFS(中間データ!$G:$G,中間データ!$D:$D,$A14,中間データ!$P:$P,">="&DATE(2025,11,1),中間データ!$P:$P,"<="&DATE(2026,1,31)),"") -> 3.1666667 | F14: =IFERROR(AVERAGEIFS(中間データ!$K:$K,中間データ!$D:$D,$A14,中間データ!$P:$P,">="&DATE(2025,11,1),中間データ!$P:$P,"<="&DATE(2026,1,31)),"") -> 3.8333333 | G14: =IFERROR(AVERAGEIFS(中間データ!$J:$J,中間データ!$D:$D,$A14,中間データ!$P:$P,">="&DATE(2025,11,1),中間データ!$P:$P,"<="&DATE(2026,1,31)),"") -> 3.5
... A18: クラウドインフラエンジニア実践研修(AWS) 中級編 | B18: =IFERROR(COUNTIFS(中間データ!$D:$D,$A18,中間データ!$P:$P,">="&DATE(2025,11,1),中間データ!$P:$P,"<="&DATE(2026,1,31)),"") -> 7 | C18: =IFERROR(AVERAGEIFS(中間データ!$F:$F,中間データ!$D:$D,$A18,中間データ!$P:$P,">="&DATE(2025,11,1),中間データ!$P:$P,"<="&DATE(2026,1,31)),"") -> 3.4285714 | D18: =IFERROR(AVERAGEIFS(中間データ!$H:$H,中間データ!$D:$D,$A18,中間データ!$P:$P,">="&DATE(2025,11,1),中間データ!$P:$P,"<="&DATE(2026,1,31)),"") -> 3.4285714 | E18: =IFERROR(AVERAGEIFS(中間データ!$G:$G,中間データ!$D:$D,$A18,中間データ!$P:$P,">="&DATE(2025,11,1),中間データ!$P:$P,"<="&DATE(2026,1,31)),"") -> 3.5714286 | F18: =IFERROR(AVERAGEIFS(中間データ!$K:$K,中間データ!$D:$D,$A18,中間データ!$P:$P,">="&DATE(2025,11,1),中間データ!$P:$P,"<="&DATE(2026,1,31)),"") -> 3.2857143 | G18: =IFERROR(AVERAGEIFS(中間データ!$J:$J,中間データ!$D:$D,$A18,中間データ!$P:$P,">="&DATE(2025,11,1),中間データ!$P:$P,"<="&DATE(2026,1,31)),"") -> 3.1428571
C19: =IFERROR(AVERAGEIFS(中間データ!$F:$F, 中間データ!$D:$D, $A19), "") -> 0 | D19: =IFERROR(AVERAGEIFS(中間データ!$H:$H, 中間データ!$D:$D, $A19), "") -> 0 | E19: =IFERROR(AVERAGEIFS(中間データ!$G:$G, 中間データ!$D:$D, $A19), "") -> 0 | F19: =IFERROR(AVERAGEIFS(中間データ!$K:$K,中間データ!$D:$D,$A19,中間データ!$P:$P,">="&DATE(2025,11,1),中間データ!$P:$P,"<="&DATE(2026,1,31)),"") | G19: =IFERROR(AVERAGEIFS(中間データ!$J:$J, 中間データ!$D:$D, $A19), "") -> 0
C20: =IFERROR(AVERAGEIFS(中間データ!$F:$F, 中間データ!$D:$D, $A20), "") -> 0 | D20: =IFERROR(AVERAGEIFS(中間データ!$H:$H, 中間データ!$D:$D, $A20), "") -> 0 | E20: =IFERROR(AVERAGEIFS(中間データ!$G:$G, 中間データ!$D:$D, $A20), "") -> 0 | F20: =IFERROR(AVERAGEIFS(中間データ!$K:$K, 中間データ!$D:$D, $A20), "") -> 0 | G20: =IFERROR(AVERAGEIFS(中間データ!$J:$J, 中間データ!$D:$D, $A20), "") -> 0
C21: =IFERROR(AVERAGEIFS(中間データ!$F:$F, 中間データ!$D:$D, $A21), "") -> 0 | D21: =IFERROR(AVERAGEIFS(中間データ!$H:$H, 中間データ!$D:$D, $A21), "") -> 0 | E21: =IFERROR(AVERAGEIFS(中間データ!$G:$G, 中間データ!$D:$D, $A21), "") -> 0 | F21: =IFERROR(AVERAGEIFS(中間データ!$K:$K, 中間データ!$D:$D, $A21), "") -> 0 | G21: =IFERROR(AVERAGEIFS(中間データ!$J:$J, 中間データ!$D:$D, $A21), "") -> 0
C22: =IFERROR(AVERAGEIFS(中間データ!$F:$F, 中間データ!$D:$D, $A22), "") -> 0 | D22: =IFERROR(AVERAGEIFS(中間データ!$H:$H, 中間データ!$D:$D, $A22), "") -> 0 | E22: =IFERROR(AVERAGEIFS(中間データ!$G:$G, 中間データ!$D:$D, $A22), "") -> 0 | F22: =IFERROR(AVERAGEIFS(中間データ!$K:$K, 中間データ!$D:$D, $A22), "") -> 0 | G22: =IFERROR(AVERAGEIFS(中間データ!$J:$J, 中間データ!$D:$D, $A22), "") -> 0
C23: =IFERROR(AVERAGEIFS(中間データ!$F:$F, 中間データ!$D:$D, $A23), "") -> 0 | D23: =IFERROR(AVERAGEIFS(中間データ!$H:$H, 中間データ!$D:$D, $A23), "") -> 0 | E23: =IFERROR(AVERAGEIFS(中間データ!$G:$G, 中間データ!$D:$D, $A23), "") -> 0 | F23: =IFERROR(AVERAGEIFS(中間データ!$K:$K, 中間データ!$D:$D, $A23), "") -> 0 | G23: =IFERROR(AVERAGEIFS(中間データ!$J:$J, 中間データ!$D:$D, $A23), "") -> 0
